Workbook
Name \A: #REF!
Name \B: #REF!
Name \C: #REF!
Name \D: #REF!
Name \E: #REF!
Name \F: #REF!
Name \G: #REF!
Name \H: #REF!
Name \I: #REF!
Name \J: #REF!
Name \K: #REF!
Name \L: #REF!
Name \M: #REF!
Name \N: #REF!
Name \O: #REF!
Name \P: #REF!
Name \Q: #REF!
Name \R: #REF!
Name \S: #REF!
Name \T: #REF!
Name \U: #REF!
Name \V: #REF!
Name \W: #REF!
Name \X: #REF!
Name \Y: #REF!
Name \Z: #REF!
Name ___BOP2: [1]BoP!#REF!
Name ___EXP5: #REF!
Name ___EXP6: #REF!
Name ___EXP7: #REF!
Name ___EXP9: #REF!
Name ___IMP2: #REF!
Name ___IMP4: #REF!
Name ___IMP6: #REF!
Name ___IMP7: #REF!
Name ___MTS2: '[2]Annual Tables'!#REF!
Name ___PAG2: [2]Index!#REF!
Name ___PAG3: [2]Index!#REF!
Name ___PAG4: [2]Index!#REF!
Name ___PAG5: [2]Index!#REF!
Name ___PAG6: [2]Index!#REF!
Name ___RES2: [1]RES!#REF!
Name ___TAB7: #REF!
Name __BOP1: #REF!
Name __IMP10: #REF!
Name __IMP8: #REF!
Name __PAG7: #REF!
Name __TAB1: #REF!
Name __TAB10: #REF!
Name __TAB12: #REF!
Name __Tab19: #REF!
Name __TAB2: #REF!
Name __Tab20: #REF!
Name __Tab21: #REF!
Name __Tab22: #REF!
Name __Tab23: #REF!
Name __Tab24: #REF!
Name __Tab26: #REF!
Name __Tab27: #REF!
Name __Tab28: #REF!

Sheet 1.Reel GSYH 
B1: Ülke Analizi
B2: Toplam Talep Analizi
B3: Reel GSYH Bileşenleri
B6: =D9+K9+M9+U9+Y9 | D6: =SUM(E9:I9) | M6: =N9+Q9 | Q6: =R9+S9 | Y6: =W9-X9
D7: Özel Tüketim Harcamaları Bileşenleri | K7: Kamu Reel Nihai Tüketim Harcamalarının Bileşenleri | M7: Brüt Sabit Sermaye Oluşumu (Gross Fixed Capital Formation) | N7: Reel Kamu Bileşenleri Brüt Sabit Sermaye Oluşumu | Q7: Reel Özel Bileşenleri Brüt Sabit Sermaye Oluşumu | U7: Stok Değişimi | W7: Net İhracat: Mal ve Hizmet Ticareti
B8: Reel GSYH (Düzey, 2008 Fiyatları-DND Milyar) | D8: Toplam Özel Tüketim (Cp) TL milyon | E8: Dayanıklı Tüketim TL milyon | F8: Yarı-Dayanıklı Tüketim TL milyon | G8: Dayanıklı Olmayan Tüketim TL milyon | H8: Hizmetler TL milyon | I8: Diğerleri, Mevsimsellikten arındırılmış TL milyon | K8: Toplam Kamu Tüketim (Cg) TL milyon | M8: Toplam Özel ve Kamu GFCF tl milyon | N8: Toplam Kamu GFCF (Ig) (Düzey, 2008 Fiyatları-DND Milyar) | O8: Kamu Makina & Ekipman (Düzey, 2008 Fiyatları-DND Milyar) | P8: Kamu İnşaat (Düzey, 2008 Fiyatları-DND Milyar) | Q8: Toplam Özel GFCF (Ip) (Düzey, 2008 Fiyatları-DND Milyar) | R8: Özel Makina & Ekipman (Düzey, 2008 Fiyatları-DND Milyar) | S8: Özel İnşaat (Düzey, 2008 Fiyatları-DND Milyar) | U8: Stok Değişimi (Düzey, 2008 Fiyatları-DND Milyar) | W8: Mal ihracatı ve Hizmetler (X) (Düzey, 2008 Fiyatları-DND Milyar) | X8: Mal ithalatı ve Hizmetler (IM) (Düzey, 2008 Fiyatları-DND Milyar) | Y8: Net İhracat (NX) (Düzey, 2008 Fiyatları-DND Milyar)
A9: Q1-1993 | U9: 23.293625 | Y9: =W9-X9 -> 0
A10: Q2-1993 | U10: 29.357175 | Y10: =W10-X10 -> 0
A11: Q3-1993 | U11: 18.210875 | Y11: =W11-X11 -> 0
A12: Q4-1993 | U12: 9.5901 | Y12: =W12-X12 -> 0
A13: Q1-1994 | U13: 15.654625 | Y13: =W13-X13 -> 0
A14: Q2-1994 | U14: 39.951925 | Y14: =W14-X14 -> 0
A15: Q3-1994 | U15: 19.97175 | Y15: =W15-X15 -> 0
A16: Q4-1994 | U16: 24.088725 | Y16: =W16-X16 -> 0
A17: Q1-1995 | U17: 26.944575 | Y17: =W17-X17 -> 0
A18: Q2-1995 | U18: 26.403175 | Y18: =W18-X18 -> 0
A19: Q3-1995 | U19: 35.6198 | Y19: =W19-X19 -> 0
A20: Q4-1995 | U20: 41.673575 | Y20: =W20-X20 -> 0
... A28: Q4-1997 | U28: 36.000075 | Y28: =W28-X28 -> 0
A29: Q1-1998 | K29: 1555721747 | W29: 3178269942 | X29: 3375501685 | Y29: =W29-X29 -> -197231743
A30: Q2-1998 | K30: 1749982774 | W30: 3570590925 | X30: 3494121398 | Y30: =W30-X30 -> 76469527
A31: Q3-1998 | K31: 2.0128767e+09 | W31: 3869069892 | X31: 3564655645 | Y31: =W31-X31 -> 304414247
A32: Q4-1998 | K32: 2317070339 | W32: 4.2503263e+09 | X32: 3759821120 | Y32: =W32-X32 -> 4.9050514e+08
A33: Q1-1999 | K33: 2870410633 | W33: 4445471150 | X33: 3863263372 | Y33: =W33-X33 -> 582207778
A34: Q2-1999 | K34: 3059143782 | W34: 4627148670 | X34: 4840368749 | Y34: =W34-X34 -> -213220079
A35: Q3-1999 | K35: 3671287486 | W35: 5025310424 | X35: 5078603827 | Y35: =W35-X35 -> -53293403
A36: Q4-1999 | K36: 4001932718 | W36: 6100147498 | X36: 6462116836 | Y36: =W36-X36 -> -361969338
A37: Q1-2000 | K37: 4459007547 | W37: 7381271101 | X37: 8655351781 | Y37: =W37-X37 -> -1274080680
A38: Q2-2000 | K38: 4955868912 | W38: 8.4274077e+09 | X38: 9499986401 | Y38: =W38-X38 -> -1.0725787e+09
A39: Q3-2000 | K39: 5358721868 | W39: 8862633102 | X39: 9720140787 | Y39: =W39-X39 -> -857507685
A40: Q4-2000 | K40: 5683358116 | W40: 9423793094 | X40: 10664823250 | Y40: =W40-X40 -> -1241030156
... A72: Q4-2008 | K72: 34531531990 | W72: 58373358520 | X72: 60996060010 | Y72: =W72-X72 -> -2622701490
A73: Q1-2009 | B73: =D73+K73+M73+U73+Y73 -> 4.1711555e+10 | D73: =SUM(E73:I73) -> 273435.7 | E73: 9472.3 | F73: 15446.1 | G73: 46185.9 | H73: 72183.6 | I73: 130147.8 | K73: 37205453390 | W73: 59129027450 | X73: 54623199750 | Y73: =W73-X73 -> 4505827700
A74: Q2-2009 | B74: =D74+K74+M74+U74+Y74 -> 3.7452284e+10 | D74: =SUM(E74:I74) -> 303049.9 | E74: 13867.4 | F74: 14821.1 | G74: 54581.3 | H74: 75667.6 | I74: 144112.5 | K74: 38245187990 | W74: 54508058600 | X74: 55301265380 | Y74: =W74-X74 -> -793206780
A75: Q3-2009 | B75: =D75+K75+M75+U75+Y75 -> 3.8455469e+10 | D75: =SUM(E75:I75) -> 340495.8 | E75: 13070.6 | F75: 16667.7 | G75: 68853.6 | H75: 78027.4 | I75: 163876.5 | K75: 39645740940 | W75: 60595791840 | X75: 61786404020 | Y75: =W75-X75 -> -1190612180
A76: Q4-2009 | B76: =D76+K76+M76+U76+Y76 -> 3.9488665e+10 | D76: =SUM(E76:I76) -> 328447.9 | E76: 13576.9 | F76: 17942.9 | G76: 57638.6 | H76: 79705.3 | I76: 159584.2 | K76: 42480006080 | W76: 60958375210 | X76: 63950044460 | Y76: =W76-X76 -> -2991669250
A77: Q1-2010 | B77: =D77+K77+M77+U77+Y77 -> 3.3797608e+10 | D77: =SUM(E77:I77) -> 300063.7 | E77: 12003.8 | F77: 16858.8 | G77: 48168.8 | H77: 75229.9 | I77: 147802.4 | K77: 41401830940 | W77: 57456631490 | X77: 6.5061155e+10 | Y77: =W77-X77 -> -7.6045231e+09
A78: Q2-2010 | B78: =D78+K78+M78+U78+Y78 -> 3.3818168e+10 | D78: =SUM(E78:I78) -> 338610.7 | E78: 14470.4 | F78: 19772.9 | G78: 57817.9 | H78: 79709.3 | I78: 166840.2 | K78: 42627117410 | W78: 63261992640 | X78: 72071281130 | Y78: =W78-X78 -> -8809288490
A79: Q3-2010 | B79: =D79+K79+M79+U79+Y79 -> 2.9346809e+10 | D79: =SUM(E79:I79) -> 394172.1 | E79: 14482.6 | F79: 20155.3 | G79: 79079.9 | H79: 85003.1 | I79: 195451.2 | K79: 44421898300 | W79: 61734911860 | X79: 76810395110 | Y79: =W79-X79 -> -15075483250
A80: Q4-2010 | B80: =D80+K80+M80+U80+Y80 -> 2.6441801e+10 | D80: =SUM(E80:I80) -> 375040.8 | E80: 18909.4 | F80: 20018.2 | G80: 62600.9 | H80: 87438.4 | I80: 186073.9 | K80: 45234082450 | W80: 65022830400 | X80: 83815486970 | Y80: =W80-X80 -> -18792656570
...

Sheet 1a. Reel GSYH Payı
B1: Ülke Analizi
B2: Toplam Talep Analizi
B3: GSYH unsurlarının payı
B9: =SUM(C12:G12) | D9: ='1.Reel GSYH '!F9/'1.Reel GSYH '!$B9*100
B10: Özel Tüketim (Cp) Harcamaların Reel GSYH içindeki Payı(%) | I10: Nihai Kamu Tüketim Harcamalarının Reel GSYH içindeki payı (%) | K10: Brüt Sabit Sermaye Oluşumunun Reel GSYH içindeki payının hesaplanması (%) | S10: Stok Değişimi in Reel GSYH içindeki payının hesaplanması (%) | U10: Net İhracat Reel GSYH içindeki payının hesaplanması (%)
B11: Toplam | C11: Dayanıklı Tüketim | D11: Yarı-Dayanıklı Tüketim | E11: Dayanıksız Tüketim | F11: Hizmetler | G11: Net İhracat | I11: Toplam | K11: Toplam Özel ve Kamu GFCF | L11: Toplam Kamu | M11: Makina & Ekipman (Kamu) | N11: İnşaat (Kamu) | O11: Toplam Özel | P11: Makina & Ekipman (Özel) | Q11: İnşaat (Özel) | U11: Mal ihracatı ve Hizmetler | V11: Mal ithalatı ve Hizmetler | W11: Net İhracat | X11: İhracat + İthalat
A12: Q1-1993 | B12: =SUM(C12:G12) -> #DIV/0! | C12: ='1.Reel GSYH '!E9/'1.Reel GSYH '!$B9*100 -> #DIV/0! | D12: ='1.Reel GSYH '!F9/'1.Reel GSYH '!$B9*100 -> #DIV/0! | E12: ='1.Reel GSYH '!G9/'1.Reel GSYH '!$B9*100 -> #DIV/0! | F12: ='1.Reel GSYH '!H9/'1.Reel GSYH '!$B9*100 -> #DIV/0! | G12: ='1.Reel GSYH '!I9/'1.Reel GSYH '!$B9*100 -> #DIV/0! | I12: ='1.Reel GSYH '!K9/'1.Reel GSYH '!$B9*100 -> #DIV/0! | K12: ='1.Reel GSYH '!M9/'1.Reel GSYH '!$B9*100 -> #DIV/0! | L12: ='1.Reel GSYH '!N9/'1.Reel GSYH '!$B9*100 -> #DIV/0! | M12: ='1.Reel GSYH '!O9/'1.Reel GSYH '!$B9*100 -> #DIV/0! | N12: ='1.Reel GSYH '!P9/'1.Reel GSYH '!$B9*100 -> #DIV/0! | O12: ='1.Reel GSYH '!Q9/'1.Reel GSYH '!$B9*100 -> #DIV/0! | P12: ='1.Reel GSYH '!R9/'1.Reel GSYH '!$B9*100 -> #DIV/0! | Q12: ='1.Reel GSYH '!S9/'1.Reel GSYH '!$B9*100 -> #DIV/0! | S12: ='1.Reel GSYH '!U9/'1.Reel GSYH '!$B9*100 -> #DIV/0! | U12: ='1.Reel GSYH '!W9/'1.Reel GSYH '!$B9*100 -> #DIV/0! | V12: ='1.Reel GSYH '!X9/'1.Reel GSYH '!$B9*100 -> #DIV/0! | W12: ='1.Reel GSYH '!Y9/'1.Reel GSYH '!$B9*100 -> #DIV/0! | X12: =(U12+V12) -> #DIV/0!
A13: Q2-1993 | B13: =SUM(C13:G13) -> #DIV/0! | C13: ='1.Reel GSYH '!E10/'1.Reel GSYH '!$B10*100 -> #DIV/0! | D13: ='1.Reel GSYH '!F10/'1.Reel GSYH '!$B10*100 -> #DIV/0! | E13: ='1.Reel GSYH '!G10/'1.Reel GSYH '!$B10*100 -> #DIV/0! | F13: ='1.Reel GSYH '!H10/'1.Reel GSYH '!$B10*100 -> #DIV/0! | G13: ='1.Reel GSYH '!I10/'1.Reel GSYH '!$B10*100 -> #DIV/0! | I13: ='1.Reel GSYH '!K10/'1.Reel GSYH '!$B10*100 -> #DIV/0! | K13: ='1.Reel GSYH '!M10/'1.Reel GSYH '!$B10*100 -> #DIV/0! | L13: ='1.Reel GSYH '!N10/'1.Reel GSYH '!$B10*100 -> #DIV/0! | M13: ='1.Reel GSYH '!O10/'1.Reel GSYH '!$B10*100 -> #DIV/0! | N13: ='1.Reel GSYH '!P10/'1.Reel GSYH '!$B10*100 -> #DIV/0! | O13: ='1.Reel GSYH '!Q10/'1.Reel GSYH '!$B10*100 -> #DIV/0! | P13: ='1.Reel GSYH '!R10/'1.Reel GSYH '!$B10*100 -> #DIV/0! | Q13: ='1.Reel GSYH '!S10/'1.Reel GSYH '!$B10*100 -> #DIV/0! | S13: ='1.Reel GSYH '!U10/'1.Reel GSYH '!$B10*100 -> #DIV/0! | U13: ='1.Reel GSYH '!W10/'1.Reel GSYH '!$B10*100 -> #DIV/0! | V13: ='1.Reel GSYH '!X10/'1.Reel GSYH '!$B10*100 -> #DIV/0! | W13: ='1.Reel GSYH '!Y10/'1.Reel GSYH '!$B10*100 -> #DIV/0! | X13: =(U13+V13) -> #DIV/0!
A14: Q3-1993 | B14: =SUM(C14:G14) -> #DIV/0! | C14: ='1.Reel GSYH '!E11/'1.Reel GSYH '!$B11*100 -> #DIV/0! | D14: ='1.Reel GSYH '!F11/'1.Reel GSYH '!$B11*100 -> #DIV/0! | E14: ='1.Reel GSYH '!G11/'1.Reel GSYH '!$B11*100 -> #DIV/0! | F14: ='1.Reel GSYH '!H11/'1.Reel GSYH '!$B11*100 -> #DIV/0! | G14: ='1.Reel GSYH '!I11/'1.Reel GSYH '!$B11*100 -> #DIV/0! | I14: ='1.Reel GSYH '!K11/'1.Reel GSYH '!$B11*100 -> #DIV/0! | K14: ='1.Reel GSYH '!M11/'1.Reel GSYH '!$B11*100 -> #DIV/0! | L14: ='1.Reel GSYH '!N11/'1.Reel GSYH '!$B11*100 -> #DIV/0! | M14: ='1.Reel GSYH '!O11/'1.Reel GSYH '!$B11*100 -> #DIV/0! | N14: ='1.Reel GSYH '!P11/'1.Reel GSYH '!$B11*100 -> #DIV/0! | O14: ='1.Reel GSYH '!Q11/'1.Reel GSYH '!$B11*100 -> #DIV/0! | P14: ='1.Reel GSYH '!R11/'1.Reel GSYH '!$B11*100 -> #DIV/0! | Q14: ='1.Reel GSYH '!S11/'1.Reel GSYH '!$B11*100 -> #DIV/0! | S14: ='1.Reel GSYH '!U11/'1.Reel GSYH '!$B11*100 -> #DIV/0! | U14: ='1.Reel GSYH '!W11/'1.Reel GSYH '!$B11*100 -> #DIV/0! | V14: ='1.Reel GSYH '!X11/'1.Reel GSYH '!$B11*100 -> #DIV/0! | W14: ='1.Reel GSYH '!Y11/'1.Reel GSYH '!$B11*100 -> #DIV/0! | X14: =(U14+V14) -> #DIV/0!
A15: Q4-1993 | B15: =SUM(C15:G15) -> #DIV/0! | C15: ='1.Reel GSYH '!E12/'1.Reel GSYH '!B12*100 -> #DIV/0! | D15: ='1.Reel GSYH '!F12/'1.Reel GSYH '!$B12*100 -> #DIV/0! | E15: ='1.Reel GSYH '!G12/'1.Reel GSYH '!$B12*100 -> #DIV/0! | F15: ='1.Reel GSYH '!H12/'1.Reel GSYH '!$B12*100 -> #DIV/0! | G15: ='1.Reel GSYH '!I12/'1.Reel GSYH '!$B12*100 -> #DIV/0! | I15: ='1.Reel GSYH '!K12/'1.Reel GSYH '!$B12*100 -> #DIV/0! | K15: ='1.Reel GSYH '!M12/'1.Reel GSYH '!$B12*100 -> #DIV/0! | L15: ='1.Reel GSYH '!N12/'1.Reel GSYH '!$B12*100 -> #DIV/0! | M15: ='1.Reel GSYH '!O12/'1.Reel GSYH '!$B12*100 -> #DIV/0! | N15: ='1.Reel GSYH '!P12/'1.Reel GSYH '!$B12*100 -> #DIV/0! | O15: ='1.Reel GSYH '!Q12/'1.Reel GSYH '!$B12*100 -> #DIV/0! | P15: ='1.Reel GSYH '!R12/'1.Reel GSYH '!$B12*100 -> #DIV/0! | Q15: ='1.Reel GSYH '!S12/'1.Reel GSYH '!$B12*100 -> #DIV/0! | S15: ='1.Reel GSYH '!U12/'1.Reel GSYH '!$B12*100 -> #DIV/0! | U15: ='1.Reel GSYH '!W12/'1.Reel GSYH '!$B12*100 -> #DIV/0! | V15: ='1.Reel GSYH '!X12/'1.Reel GSYH '!$B12*100 -> #DIV/0! | W15: ='1.Reel GSYH '!Y12/'1.Reel GSYH '!$B12*100 -> #DIV/0! | X15: =(U15+V15) -> #DIV/0!
A16: Q1-1994 | B16: =SUM(C16:G16) -> #DIV/0! | C16: ='1.Reel GSYH '!E13/'1.Reel GSYH '!B13*100 -> #DIV/0! | D16: ='1.Reel GSYH '!F13/'1.Reel GSYH '!$B13*100 -> #DIV/0! | E16: ='1.Reel GSYH '!G13/'1.Reel GSYH '!$B13*100 -> #DIV/0! | F16: ='1.Reel GSYH '!H13/'1.Reel GSYH '!$B13*100 -> #DIV/0! | G16: ='1.Reel GSYH '!I13/'1.Reel GSYH '!$B13*100 -> #DIV/0! | I16: ='1.Reel GSYH '!K13/'1.Reel GSYH '!$B13*100 -> #DIV/0! | K16: ='1.Reel GSYH '!M13/'1.Reel GSYH '!$B13*100 -> #DIV/0! | L16: ='1.Reel GSYH '!N13/'1.Reel GSYH '!$B13*100 -> #DIV/0! | M16: ='1.Reel GSYH '!O13/'1.Reel GSYH '!$B13*100 -> #DIV/0! | N16: ='1.Reel GSYH '!P13/'1.Reel GSYH '!$B13*100 -> #DIV/0! | O16: ='1.Reel GSYH '!Q13/'1.Reel GSYH '!$B13*100 -> #DIV/0! | P16: ='1.Reel GSYH '!R13/'1.Reel GSYH '!$B13*100 -> #DIV/0! | Q16: ='1.Reel GSYH '!S13/'1.Reel GSYH '!$B13*100 -> #DIV/0! | S16: ='1.Reel GSYH '!U13/'1.Reel GSYH '!$B13*100 -> #DIV/0! | U16: ='1.Reel GSYH '!W13/'1.Reel GSYH '!$B13*100 -> #DIV/0! | V16: ='1.Reel GSYH '!X13/'1.Reel GSYH '!$B13*100 -> #DIV/0! | W16: ='1.Reel GSYH '!Y13/'1.Reel GSYH '!$B13*100 -> #DIV/0! | X16: =(U16+V16) -> #DIV/0!
A17: Q2-1994 | B17: =SUM(C17:G17) -> #DIV/0! | C17: ='1.Reel GSYH '!E14/'1.Reel GSYH '!B14*100 -> #DIV/0! | D17: ='1.Reel GSYH '!F14/'1.Reel GSYH '!$B14*100 -> #DIV/0! | E17: ='1.Reel GSYH '!G14/'1.Reel GSYH '!$B14*100 -> #DIV/0! | F17: ='1.Reel GSYH '!H14/'1.Reel GSYH '!$B14*100 -> #DIV/0! | G17: ='1.Reel GSYH '!I14/'1.Reel GSYH '!$B14*100 -> #DIV/0! | I17: ='1.Reel GSYH '!K14/'1.Reel GSYH '!$B14*100 -> #DIV/0! | K17: ='1.Reel GSYH '!M14/'1.Reel GSYH '!$B14*100 -> #DIV/0! | L17: ='1.Reel GSYH '!N14/'1.Reel GSYH '!$B14*100 -> #DIV/0! | M17: ='1.Reel GSYH '!O14/'1.Reel GSYH '!$B14*100 -> #DIV/0! | N17: ='1.Reel GSYH '!P14/'1.Reel GSYH '!$B14*100 -> #DIV/0! | O17: ='1.Reel GSYH '!Q14/'1.Reel GSYH '!$B14*100 -> #DIV/0! | P17: ='1.Reel GSYH '!R14/'1.Reel GSYH '!$B14*100 -> #DIV/0! | Q17: ='1.Reel GSYH '!S14/'1.Reel GSYH '!$B14*100 -> #DIV/0! | S17: ='1.Reel GSYH '!U14/'1.Reel GSYH '!$B14*100 -> #DIV/0! | U17: ='1.Reel GSYH '!W14/'1.Reel GSYH '!$B14*100 -> #DIV/0! | V17: ='1.Reel GSYH '!X14/'1.Reel GSYH '!$B14*100 -> #DIV/0! | W17: ='1.Reel GSYH '!Y14/'1.Reel GSYH '!$B14*100 -> #DIV/0! | X17: =(U17+V17) -> #DIV/0!
A18: Q3-1994 | B18: =SUM(C18:G18) -> #DIV/0! | C18: ='1.Reel GSYH '!E15/'1.Reel GSYH '!B15*100 -> #DIV/0! | D18: ='1.Reel GSYH '!F15/'1.Reel GSYH '!$B15*100 -> #DIV/0! | E18: ='1.Reel GSYH '!G15/'1.Reel GSYH '!$B15*100 -> #DIV/0! | F18: ='1.Reel GSYH '!H15/'1.Reel GSYH '!$B15*100 -> #DIV/0! | G18: ='1.Reel GSYH '!I15/'1.Reel GSYH '!$B15*100 -> #DIV/0! | I18: ='1.Reel GSYH '!K15/'1.Reel GSYH '!$B15*100 -> #DIV/0! | K18: ='1.Reel GSYH '!M15/'1.Reel GSYH '!$B15*100 -> #DIV/0! | L18: ='1.Reel GSYH '!N15/'1.Reel GSYH '!$B15*100 -> #DIV/0! | M18: ='1.Reel GSYH '!O15/'1.Reel GSYH '!$B15*100 -> #DIV/0! | N18: ='1.Reel GSYH '!P15/'1.Reel GSYH '!$B15*100 -> #DIV/0! | O18: ='1.Reel GSYH '!Q15/'1.Reel GSYH '!$B15*100 -> #DIV/0! | P18: ='1.Reel GSYH '!R15/'1.Reel GSYH '!$B15*100 -> #DIV/0! | Q18: ='1.Reel GSYH '!S15/'1.Reel GSYH '!$B15*100 -> #DIV/0! | S18: ='1.Reel GSYH '!U15/'1.Reel GSYH '!$B15*100 -> #DIV/0! | U18: ='1.Reel GSYH '!W15/'1.Reel GSYH '!$B15*100 -> #DIV/0! | V18: ='1.Reel GSYH '!X15/'1.Reel GSYH '!$B15*100 -> #DIV/0! | W18: ='1.Reel GSYH '!Y15/'1.Reel GSYH '!$B15*100 -> #DIV/0! | X18: =(U18+V18) -> #DIV/0!
A19: Q4-1994 | B19: =SUM(C19:G19) -> #DIV/0! | C19: ='1.Reel GSYH '!E16/'1.Reel GSYH '!B16*100 -> #DIV/0! | D19: ='1.Reel GSYH '!F16/'1.Reel GSYH '!$B16*100 -> #DIV/0! | E19: ='1.Reel GSYH '!G16/'1.Reel GSYH '!$B16*100 -> #DIV/0! | F19: ='1.Reel GSYH '!H16/'1.Reel GSYH '!$B16*100 -> #DIV/0! | G19: ='1.Reel GSYH '!I16/'1.Reel GSYH '!$B16*100 -> #DIV/0! | I19: ='1.Reel GSYH '!K16/'1.Reel GSYH '!$B16*100 -> #DIV/0! | K19: ='1.Reel GSYH '!M16/'1.Reel GSYH '!$B16*100 -> #DIV/0! | L19: ='1.Reel GSYH '!N16/'1.Reel GSYH '!$B16*100 -> #DIV/0! | M19: ='1.Reel GSYH '!O16/'1.Reel GSYH '!$B16*100 -> #DIV/0! | N19: ='1.Reel GSYH '!P16/'1.Reel GSYH '!$B16*100 -> #DIV/0! | O19: ='1.Reel GSYH '!Q16/'1.Reel GSYH '!$B16*100 -> #DIV/0! | P19: ='1.Reel GSYH '!R16/'1.Reel GSYH '!$B16*100 -> #DIV/0! | Q19: ='1.Reel GSYH '!S16/'1.Reel GSYH '!$B16*100 -> #DIV/0! | S19: ='1.Reel GSYH '!U16/'1.Reel GSYH '!$B16*100 -> #DIV/0! | U19: ='1.Reel GSYH '!W16/'1.Reel GSYH '!$B16*100 -> #DIV/0! | V19: ='1.Reel GSYH '!X16/'1.Reel GSYH '!$B16*100 -> #DIV/0! | W19: ='1.Reel GSYH '!Y16/'1.Reel GSYH '!$B16*100 -> #DIV/0! | X19: =(U19+V19) -> #DIV/0!
A20: Q1-1995 | B20: =SUM(C20:G20) -> #DIV/0! | C20: ='1.Reel GSYH '!E17/'1.Reel GSYH '!B17*100 -> #DIV/0! | D20: ='1.Reel GSYH '!F17/'1.Reel GSYH '!$B17*100 -> #DIV/0! | E20: ='1.Reel GSYH '!G17/'1.Reel GSYH '!$B17*100 -> #DIV/0! | F20: ='1.Reel GSYH '!H17/'1.Reel GSYH '!$B17*100 -> #DIV/0! | G20: ='1.Reel GSYH '!I17/'1.Reel GSYH '!$B17*100 -> #DIV/0! | I20: ='1.Reel GSYH '!K17/'1.Reel GSYH '!$B17*100 -> #DIV/0! | K20: ='1.Reel GSYH '!M17/'1.Reel GSYH '!$B17*100 -> #DIV/0! | L20: ='1.Reel GSYH '!N17/'1.Reel GSYH '!$B17*100 -> #DIV/0! | M20: ='1.Reel GSYH '!O17/'1.Reel GSYH '!$B17*100 -> #DIV/0! | N20: ='1.Reel GSYH '!P17/'1.Reel GSYH '!$B17*100 -> #DIV/0! | O20: ='1.Reel GSYH '!Q17/'1.Reel GSYH '!$B17*100 -> #DIV/0! | P20: ='1.Reel GSYH '!R17/'1.Reel GSYH '!$B17*100 -> #DIV/0! | Q20: ='1.Reel GSYH '!S17/'1.Reel GSYH '!$B17*100 -> #DIV/0! | S20: ='1.Reel GSYH '!U17/'1.Reel GSYH '!$B17*100 -> #DIV/0! | U20: ='1.Reel GSYH '!W17/'1.Reel GSYH '!$B17*100 -> #DIV/0! | V20: ='1.Reel GSYH '!X17/'1.Reel GSYH '!$B17*100 -> #DIV/0! | W20: ='1.Reel GSYH '!Y17/'1.Reel GSYH '!$B17*100 -> #DIV/0! | X20: =(U20+V20) -> #DIV/0!
A21: Q2-1995 | B21: =SUM(C21:G21) -> #DIV/0! | C21: ='1.Reel GSYH '!E18/'1.Reel GSYH '!B18*100 -> #DIV/0! | D21: ='1.Reel GSYH '!F18/'1.Reel GSYH '!$B18*100 -> #DIV/0! | E21: ='1.Reel GSYH '!G18/'1.Reel GSYH '!$B18*100 -> #DIV/0! | F21: ='1.Reel GSYH '!H18/'1.Reel GSYH '!$B18*100 -> #DIV/0! | G21: ='1.Reel GSYH '!I18/'1.Reel GSYH '!$B18*100 -> #DIV/0! | I21: ='1.Reel GSYH '!K18/'1.Reel GSYH '!$B18*100 -> #DIV/0! | K21: ='1.Reel GSYH '!M18/'1.Reel GSYH '!$B18*100 -> #DIV/0! | L21: ='1.Reel GSYH '!N18/'1.Reel GSYH '!$B18*100 -> #DIV/0! | M21: ='1.Reel GSYH '!O18/'1.Reel GSYH '!$B18*100 -> #DIV/0! | N21: ='1.Reel GSYH '!P18/'1.Reel GSYH '!$B18*100 -> #DIV/0! | O21: ='1.Reel GSYH '!Q18/'1.Reel GSYH '!$B18*100 -> #DIV/0! | P21: ='1.Reel GSYH '!R18/'1.Reel GSYH '!$B18*100 -> #DIV/0! | Q21: ='1.Reel GSYH '!S18/'1.Reel GSYH '!$B18*100 -> #DIV/0! | S21: ='1.Reel GSYH '!U18/'1.Reel GSYH '!$B18*100 -> #DIV/0! | U21: ='1.Reel GSYH '!W18/'1.Reel GSYH '!$B18*100 -> #DIV/0! | V21: ='1.Reel GSYH '!X18/'1.Reel GSYH '!$B18*100 -> #DIV/0! | W21: ='1.Reel GSYH '!Y18/'1.Reel GSYH '!$B18*100 -> #DIV/0! | X21: =(U21+V21) -> #DIV/0!
A22: Q3-1995 | B22: =SUM(C22:G22) -> #DIV/0! | C22: ='1.Reel GSYH '!E19/'1.Reel GSYH '!B19*100 -> #DIV/0! | D22: ='1.Reel GSYH '!F19/'1.Reel GSYH '!$B19*100 -> #DIV/0! | E22: ='1.Reel GSYH '!G19/'1.Reel GSYH '!$B19*100 -> #DIV/0! | F22: ='1.Reel GSYH '!H19/'1.Reel GSYH '!$B19*100 -> #DIV/0! | G22: ='1.Reel GSYH '!I19/'1.Reel GSYH '!$B19*100 -> #DIV/0! | I22: ='1.Reel GSYH '!K19/'1.Reel GSYH '!$B19*100 -> #DIV/0! | K22: ='1.Reel GSYH '!M19/'1.Reel GSYH '!$B19*100 -> #DIV/0! | L22: ='1.Reel GSYH '!N19/'1.Reel GSYH '!$B19*100 -> #DIV/0! | M22: ='1.Reel GSYH '!O19/'1.Reel GSYH '!$B19*100 -> #DIV/0! | N22: ='1.Reel GSYH '!P19/'1.Reel GSYH '!$B19*100 -> #DIV/0! | O22: ='1.Reel GSYH '!Q19/'1.Reel GSYH '!$B19*100 -> #DIV/0! | P22: ='1.Reel GSYH '!R19/'1.Reel GSYH '!$B19*100 -> #DIV/0! | Q22: ='1.Reel GSYH '!S19/'1.Reel GSYH '!$B19*100 -> #DIV/0! | S22: ='1.Reel GSYH '!U19/'1.Reel GSYH '!$B19*100 -> #DIV/0! | U22: ='1.Reel GSYH '!W19/'1.Reel GSYH '!$B19*100 -> #DIV/0! | V22: ='1.Reel GSYH '!X19/'1.Reel GSYH '!$B19*100 -> #DIV/0! | W22: ='1.Reel GSYH '!Y19/'1.Reel GSYH '!$B19*100 -> #DIV/0! | X22: =(U22+V22) -> #DIV/0!
A23: Q4-1995 | B23: =SUM(C23:G23) -> #DIV/0! | C23: ='1.Reel GSYH '!E20/'1.Reel GSYH '!B20*100 -> #DIV/0! | D23: ='1.Reel GSYH '!F20/'1.Reel GSYH '!$B20*100 -> #DIV/0! | E23: ='1.Reel GSYH '!G20/'1.Reel GSYH '!$B20*100 -> #DIV/0! | F23: ='1.Reel GSYH '!H20/'1.Reel GSYH '!$B20*100 -> #DIV/0! | G23: ='1.Reel GSYH '!I20/'1.Reel GSYH '!$B20*100 -> #DIV/0! | I23: ='1.Reel GSYH '!K20/'1.Reel GSYH '!$B20*100 -> #DIV/0! | K23: ='1.Reel GSYH '!M20/'1.Reel GSYH '!$B20*100 -> #DIV/0! | L23: ='1.Reel GSYH '!N20/'1.Reel GSYH '!$B20*100 -> #DIV/0! | M23: ='1.Reel GSYH '!O20/'1.Reel GSYH '!$B20*100 -> #DIV/0! | N23: ='1.Reel GSYH '!P20/'1.Reel GSYH '!$B20*100 -> #DIV/0! | O23: ='1.Reel GSYH '!Q20/'1.Reel GSYH '!$B20*100 -> #DIV/0! | P23: ='1.Reel GSYH '!R20/'1.Reel GSYH '!$B20*100 -> #DIV/0! | Q23: ='1.Reel GSYH '!S20/'1.Reel GSYH '!$B20*100 -> #DIV/0! | S23: ='1.Reel GSYH '!U20/'1.Reel GSYH '!$B20*100 -> #DIV/0! | U23: ='1.Reel GSYH '!W20/'1.Reel GSYH '!$B20*100 -> #DIV/0! | V23: ='1.Reel GSYH '!X20/'1.Reel GSYH '!$B20*100 -> #DIV/0! | W23: ='1.Reel GSYH '!Y20/'1.Reel GSYH '!$B20*100 -> #DIV/0! | X23: =(U23+V23) -> #DIV/0!
A24: Q1-1996 | B24: =SUM(C24:G24) -> #DIV/0! | C24: ='1.Reel GSYH '!E21/'1.Reel GSYH '!B21*100 -> #DIV/0! | D24: ='1.Reel GSYH '!F21/'1.Reel GSYH '!$B21*100 -> #DIV/0! | E24: ='1.Reel GSYH '!G21/'1.Reel GSYH '!$B21*100 -> #DIV/0! | F24: ='1.Reel GSYH '!H21/'1.Reel GSYH '!$B21*100 -> #DIV/0! | G24: ='1.Reel GSYH '!I21/'1.Reel GSYH '!$B21*100 -> #DIV/0! | I24: ='1.Reel GSYH '!K21/'1.Reel GSYH '!$B21*100 -> #DIV/0! | K24: ='1.Reel GSYH '!M21/'1.Reel GSYH '!$B21*100 -> #DIV/0! | L24: ='1.Reel GSYH '!N21/'1.Reel GSYH '!$B21*100 -> #DIV/0! | M24: ='1.Reel GSYH '!O21/'1.Reel GSYH '!$B21*100 -> #DIV/0! | N24: ='1.Reel GSYH '!P21/'1.Reel GSYH '!$B21*100 -> #DIV/0! | O24: ='1.Reel GSYH '!Q21/'1.Reel GSYH '!$B21*100 -> #DIV/0! | P24: ='1.Reel GSYH '!R21/'1.Reel GSYH '!$B21*100 -> #DIV/0! | Q24: ='1.Reel GSYH '!S21/'1.Reel GSYH '!$B21*100 -> #DIV/0! | S24: ='1.Reel GSYH '!U21/'1.Reel GSYH '!$B21*100 -> #DIV/0! | U24: ='1.Reel GSYH '!W21/'1.Reel GSYH '!$B21*100 -> #DIV/0! | V24: ='1.Reel GSYH '!X21/'1.Reel GSYH '!$B21*100 -> #DIV/0! | W24: ='1.Reel GSYH '!Y21/'1.Reel GSYH '!$B21*100 -> #DIV/0! | X24: =(U24+V24) -> #DIV/0!
A25: Q2-1996 | B25: =SUM(C25:G25) -> #DIV/0! | C25: ='1.Reel GSYH '!E22/'1.Reel GSYH '!B22*100 -> #DIV/0! | D25: ='1.Reel GSYH '!F22/'1.Reel GSYH '!$B22*100 -> #DIV/0! | E25: ='1.Reel GSYH '!G22/'1.Reel GSYH '!$B22*100 -> #DIV/0! | F25: ='1.Reel GSYH '!H22/'1.Reel GSYH '!$B22*100 -> #DIV/0! | G25: ='1.Reel GSYH '!I22/'1.Reel GSYH '!$B22*100 -> #DIV/0! | I25: ='1.Reel GSYH '!K22/'1.Reel GSYH '!$B22*100 -> #DIV/0! | K25: ='1.Reel GSYH '!M22/'1.Reel GSYH '!$B22*100 -> #DIV/0! | L25: ='1.Reel GSYH '!N22/'1.Reel GSYH '!$B22*100 -> #DIV/0! | M25: ='1.Reel GSYH '!O22/'1.Reel GSYH '!$B22*100 -> #DIV/0! | N25: ='1.Reel GSYH '!P22/'1.Reel GSYH '!$B22*100 -> #DIV/0! | O25: ='1.Reel GSYH '!Q22/'1.Reel GSYH '!$B22*100 -> #DIV/0! | P25: ='1.Reel GSYH '!R22/'1.Reel GSYH '!$B22*100 -> #DIV/0! | Q25: ='1.Reel GSYH '!S22/'1.Reel GSYH '!$B22*100 -> #DIV/0! | S25: ='1.Reel GSYH '!U22/'1.Reel GSYH '!$B22*100 -> #DIV/0! | U25: ='1.Reel GSYH '!W22/'1.Reel GSYH '!$B22*100 -> #DIV/0! | V25: ='1.Reel GSYH '!X22/'1.Reel GSYH '!$B22*100 -> #DIV/0! | W25: ='1.Reel GSYH '!Y22/'1.Reel GSYH '!$B22*100 -> #DIV/0! | X25: =(U25+V25) -> #DIV/0!
A26: Q3-1996 | B26: =SUM(C26:G26) -> #DIV/0! | C26: ='1.Reel GSYH '!E23/'1.Reel GSYH '!B23*100 -> #DIV/0! | D26: ='1.Reel GSYH '!F23/'1.Reel GSYH '!$B23*100 -> #DIV/0! | E26: ='1.Reel GSYH '!G23/'1.Reel GSYH '!$B23*100 -> #DIV/0! | F26: ='1.Reel GSYH '!H23/'1.Reel GSYH '!$B23*100 -> #DIV/0! | G26: ='1.Reel GSYH '!I23/'1.Reel GSYH '!$B23*100 -> #DIV/0! | I26: ='1.Reel GSYH '!K23/'1.Reel GSYH '!$B23*100 -> #DIV/0! | K26: ='1.Reel GSYH '!M23/'1.Reel GSYH '!$B23*100 -> #DIV/0! | L26: ='1.Reel GSYH '!N23/'1.Reel GSYH '!$B23*100 -> #DIV/0! | M26: ='1.Reel GSYH '!O23/'1.Reel GSYH '!$B23*100 -> #DIV/0! | N26: ='1.Reel GSYH '!P23/'1.Reel GSYH '!$B23*100 -> #DIV/0! | O26: ='1.Reel GSYH '!Q23/'1.Reel GSYH '!$B23*100 -> #DIV/0! | P26: ='1.Reel GSYH '!R23/'1.Reel GSYH '!$B23*100 -> #DIV/0! | Q26: ='1.Reel GSYH '!S23/'1.Reel GSYH '!$B23*100 -> #DIV/0! | S26: ='1.Reel GSYH '!U23/'1.Reel GSYH '!$B23*100 -> #DIV/0! | U26: ='1.Reel GSYH '!W23/'1.Reel GSYH '!$B23*100 -> #DIV/0! | V26: ='1.Reel GSYH '!X23/'1.Reel GSYH '!$B23*100 -> #DIV/0! | W26: ='1.Reel GSYH '!Y23/'1.Reel GSYH '!$B23*100 -> #DIV/0! | X26: =(U26+V26) -> #DIV/0!
... A75: Q4-2008 | B75: =SUM(C75:G75) -> #DIV/0! | C75: ='1.Reel GSYH '!E72/'1.Reel GSYH '!B72*100 -> #DIV/0! | D75: ='1.Reel GSYH '!F72/'1.Reel GSYH '!$B72*100 -> #DIV/0! | E75: ='1.Reel GSYH '!G72/'1.Reel GSYH '!$B72*100 -> #DIV/0! | F75: ='1.Reel GSYH '!H72/'1.Reel GSYH '!$B72*100 -> #DIV/0! | G75: ='1.Reel GSYH '!I72/'1.Reel GSYH '!$B72*100 -> #DIV/0! | I75: ='1.Reel GSYH '!K72/'1.Reel GSYH '!$B72*100 -> #DIV/0! | K75: ='1.Reel GSYH '!M72/'1.Reel GSYH '!$B72*100 -> #DIV/0! | L75: ='1.Reel GSYH '!N72/'1.Reel GSYH '!$B72*100 -> #DIV/0! | M75: ='1.Reel GSYH '!O72/'1.Reel GSYH '!$B72*100 -> #DIV/0! | N75: ='1.Reel GSYH '!P72/'1.Reel GSYH '!$B72*100 -> #DIV/0! | O75: ='1.Reel GSYH '!Q72/'1.Reel GSYH '!$B72*100 -> #DIV/0! | P75: ='1.Reel GSYH '!R72/'1.Reel GSYH '!$B72*100 -> #DIV/0! | Q75: ='1.Reel GSYH '!S72/'1.Reel GSYH '!$B72*100 -> #DIV/0! | S75: ='1.Reel GSYH '!U72/'1.Reel GSYH '!$B72*100 -> #DIV/0! | U75: ='1.Reel GSYH '!W72/'1.Reel GSYH '!$B72*100 -> #DIV/0! | V75: ='1.Reel GSYH '!X72/'1.Reel GSYH '!$B72*100 -> #DIV/0! | W75: ='1.Reel GSYH '!Y72/'1.Reel GSYH '!$B72*100 -> #DIV/0! | X75: =(U75+V75) -> #DIV/0!
A76: Q1-2009 | B76: =SUM(C76:G76) -> 133815.6 | D76: 15446.1 | E76: 46185.9 | F76: 72183.6 | G76: ='1.Reel GSYH '!I73/'1.Reel GSYH '!$B73*100 -> 0.00031201858 | I76: ='1.Reel GSYH '!K73/'1.Reel GSYH '!$B73*100 -> 89.196995 | K76: ='1.Reel GSYH '!M73/'1.Reel GSYH '!$B73*100 -> 0 | L76: ='1.Reel GSYH '!N73/'1.Reel GSYH '!$B73*100 -> 0 | M76: ='1.Reel GSYH '!O73/'1.Reel GSYH '!$B73*100 -> 0 | N76: ='1.Reel GSYH '!P73/'1.Reel GSYH '!$B73*100 -> 0 | O76: ='1.Reel GSYH '!Q73/'1.Reel GSYH '!$B73*100 -> 0 | P76: ='1.Reel GSYH '!R73/'1.Reel GSYH '!$B73*100 -> 0 | Q76: ='1.Reel GSYH '!S73/'1.Reel GSYH '!$B73*100 -> 0 | S76: ='1.Reel GSYH '!U73/'1.Reel GSYH '!$B73*100 -> 0 | U76: ='1.Reel GSYH '!W73/'1.Reel GSYH '!$B73*100 -> 141.75695 | V76: ='1.Reel GSYH '!X73/'1.Reel GSYH '!$B73*100 -> 130.9546 | W76: ='1.Reel GSYH '!Y73/'1.Reel GSYH '!$B73*100 -> 10.802349 | X76: =(U76+V76) -> 272.71155
A77: Q2-2009 | B77: =SUM(C77:G77) -> 158937.4 | C77: 13867.4 | D77: 14821.1 | E77: 54581.3 | F77: 75667.6 | G77: ='1.Reel GSYH '!I74/'1.Reel GSYH '!$B74*100 -> 0.00038478961 | I77: ='1.Reel GSYH '!K74/'1.Reel GSYH '!$B74*100 -> 102.1171 | K77: ='1.Reel GSYH '!M74/'1.Reel GSYH '!$B74*100 -> 0 | L77: ='1.Reel GSYH '!N74/'1.Reel GSYH '!$B74*100 -> 0 | M77: ='1.Reel GSYH '!O74/'1.Reel GSYH '!$B74*100 -> 0 | N77: ='1.Reel GSYH '!P74/'1.Reel GSYH '!$B74*100 -> 0 | O77: ='1.Reel GSYH '!Q74/'1.Reel GSYH '!$B74*100 -> 0 | P77: ='1.Reel GSYH '!R74/'1.Reel GSYH '!$B74*100 -> 0 | Q77: ='1.Reel GSYH '!S74/'1.Reel GSYH '!$B74*100 -> 0 | S77: ='1.Reel GSYH '!U74/'1.Reel GSYH '!$B74*100 -> 0 | U77: ='1.Reel GSYH '!W74/'1.Reel GSYH '!$B74*100 -> 145.54001 | V77: ='1.Reel GSYH '!X74/'1.Reel GSYH '!$B74*100 -> 147.65792 | W77: ='1.Reel GSYH '!Y74/'1.Reel GSYH '!$B74*100 -> -2.117913 | X77: =(U77+V77) -> 293.19793
A78: Q3-2009 | B78: =SUM(C78:G78) -> 176619.3 | C78: 13070.6 | D78: 16667.7 | E78: 68853.6 | F78: 78027.4 | G78: ='1.Reel GSYH '!I75/'1.Reel GSYH '!$B75*100 -> 0.00042614615 | I78: ='1.Reel GSYH '!K75/'1.Reel GSYH '!$B75*100 -> 103.09519 | K78: ='1.Reel GSYH '!M75/'1.Reel GSYH '!$B75*100 -> 0 | L78: ='1.Reel GSYH '!N75/'1.Reel GSYH '!$B75*100 -> 0 | M78: ='1.Reel GSYH '!O75/'1.Reel GSYH '!$B75*100 -> 0 | N78: ='1.Reel GSYH '!P75/'1.Reel GSYH '!$B75*100 -> 0 | O78: ='1.Reel GSYH '!Q75/'1.Reel GSYH '!$B75*100 -> 0 | P78: ='1.Reel GSYH '!R75/'1.Reel GSYH '!$B75*100 -> 0 | Q78: ='1.Reel GSYH '!S75/'1.Reel GSYH '!$B75*100 -> 0 | S78: ='1.Reel GSYH '!U75/'1.Reel GSYH '!$B75*100 -> 0 | U78: ='1.Reel GSYH '!W75/'1.Reel GSYH '!$B75*100 -> 157.57392 | V78: ='1.Reel GSYH '!X75/'1.Reel GSYH '!$B75*100 -> 160.67 | W78: ='1.Reel GSYH '!Y75/'1.Reel GSYH '!$B75*100 -> -3.0960802 | X78: =(U78+V78) -> 318.24393
A79: Q4-2009 | B79: =SUM(C79:G79) -> 168863.7 | C79: 13576.9 | D79: 17942.9 | E79: 57638.6 | F79: 79705.3 | G79: ='1.Reel GSYH '!I76/'1.Reel GSYH '!$B76*100 -> 0.0004041266 | I79: ='1.Reel GSYH '!K76/'1.Reel GSYH '!$B76*100 -> 107.57519 | K79: ='1.Reel GSYH '!M76/'1.Reel GSYH '!$B76*100 -> 0 | L79: ='1.Reel GSYH '!N76/'1.Reel GSYH '!$B76*100 -> 0 | M79: ='1.Reel GSYH '!O76/'1.Reel GSYH '!$B76*100 -> 0 | N79: ='1.Reel GSYH '!P76/'1.Reel GSYH '!$B76*100 -> 0 | O79: ='1.Reel GSYH '!Q76/'1.Reel GSYH '!$B76*100 -> 0 | P79: ='1.Reel GSYH '!R76/'1.Reel GSYH '!$B76*100 -> 0 | Q79: ='1.Reel GSYH '!S76/'1.Reel GSYH '!$B76*100 -> 0 | S79: ='1.Reel GSYH '!U76/'1.Reel GSYH '!$B76*100 -> 0 | U79: ='1.Reel GSYH '!W76/'1.Reel GSYH '!$B76*100 -> 154.3693 | V79: ='1.Reel GSYH '!X76/'1.Reel GSYH '!$B76*100 -> 161.94532 | W79: ='1.Reel GSYH '!Y76/'1.Reel GSYH '!$B76*100 -> -7.5760202 | X79: =(U79+V79) -> 316.31462
A80: Q1-2010 | B80: =SUM(C80:G80) -> 152261.3 | C80: 12003.8 | D80: 16858.8 | E80: 48168.8 | F80: 75229.9 | G80: ='1.Reel GSYH '!I77/'1.Reel GSYH '!$B77*100 -> 0.00043731616 | I80: ='1.Reel GSYH '!K77/'1.Reel GSYH '!$B77*100 -> 122.49929 | K80: ='1.Reel GSYH '!M77/'1.Reel GSYH '!$B77*100 -> 0 | L80: ='1.Reel GSYH '!N77/'1.Reel GSYH '!$B77*100 -> 0 | M80: ='1.Reel GSYH '!O77/'1.Reel GSYH '!$B77*100 -> 0 | N80: ='1.Reel GSYH '!P77/'1.Reel GSYH '!$B77*100 -> 0 | O80: ='1.Reel GSYH '!Q77/'1.Reel GSYH '!$B77*100 -> 0 | P80: ='1.Reel GSYH '!R77/'1.Reel GSYH '!$B77*100 -> 0 | Q80: ='1.Reel GSYH '!S77/'1.Reel GSYH '!$B77*100 -> 0 | S80: ='1.Reel GSYH '!U77/'1.Reel GSYH '!$B77*100 -> 0 | U80: ='1.Reel GSYH '!W77/'1.Reel GSYH '!$B77*100 -> 170.00207 | V80: ='1.Reel GSYH '!X77/'1.Reel GSYH '!$B77*100 -> 192.50225 | W80: ='1.Reel GSYH '!Y77/'1.Reel GSYH '!$B77*100 -> -22.500181 | X80: =(U80+V80) -> 362.50431
A81: Q2-2010 | B81: =SUM(C81:G81) -> 171770.5 | C81: 14470.4 | D81: 19772.9 | E81: 57817.9 | F81: 79709.3 | G81: ='1.Reel GSYH '!I78/'1.Reel GSYH '!$B78*100 -> 0.00049334489 | I81: ='1.Reel GSYH '!K78/'1.Reel GSYH '!$B78*100 -> 126.04798 | K81: ='1.Reel GSYH '!M78/'1.Reel GSYH '!$B78*100 -> 0 | L81: ='1.Reel GSYH '!N78/'1.Reel GSYH '!$B78*100 -> 0 | M81: ='1.Reel GSYH '!O78/'1.Reel GSYH '!$B78*100 -> 0 | N81: ='1.Reel GSYH '!P78/'1.Reel GSYH '!$B78*100 -> 0 | O81: ='1.Reel GSYH '!Q78/'1.Reel GSYH '!$B78*100 -> 0 | P81: ='1.Reel GSYH '!R78/'1.Reel GSYH '!$B78*100 -> 0 | Q81: ='1.Reel GSYH '!S78/'1.Reel GSYH '!$B78*100 -> 0 | S81: ='1.Reel GSYH '!U78/'1.Reel GSYH '!$B78*100 -> 0 | U81: ='1.Reel GSYH '!W78/'1.Reel GSYH '!$B78*100 -> 187.06511 | V81: ='1.Reel GSYH '!X78/'1.Reel GSYH '!$B78*100 -> 213.11409 | W81: ='1.Reel GSYH '!Y78/'1.Reel GSYH '!$B78*100 -> -26.048982 | X81: =(U81+V81) -> 400.1792
A82: Q3-2010 | B82: =SUM(C82:G82) -> 198720.9 | C82: 14482.6 | D82: 20155.3 | E82: 79079.9 | F82: 85003.1 | G82: ='1.Reel GSYH '!I79/'1.Reel GSYH '!$B79*100 -> 0.00066600494 | I82: ='1.Reel GSYH '!K79/'1.Reel GSYH '!$B79*100 -> 151.36875 | K82: ='1.Reel GSYH '!M79/'1.Reel GSYH '!$B79*100 -> 0 | L82: ='1.Reel GSYH '!N79/'1.Reel GSYH '!$B79*100 -> 0 | M82: ='1.Reel GSYH '!O79/'1.Reel GSYH '!$B79*100 -> 0 | N82: ='1.Reel GSYH '!P79/'1.Reel GSYH '!$B79*100 -> 0 | O82: ='1.Reel GSYH '!Q79/'1.Reel GSYH '!$B79*100 -> 0 | P82: ='1.Reel GSYH '!R79/'1.Reel GSYH '!$B79*100 -> 0 | Q82: ='1.Reel GSYH '!S79/'1.Reel GSYH '!$B79*100 -> 0 | S82: ='1.Reel GSYH '!U79/'1.Reel GSYH '!$B79*100 -> 0 | U82: ='1.Reel GSYH '!W79/'1.Reel GSYH '!$B79*100 -> 210.36328 | V82: ='1.Reel GSYH '!X79/'1.Reel GSYH '!$B79*100 -> 261.73338 | W82: ='1.Reel GSYH '!Y79/'1.Reel GSYH '!$B79*100 -> -51.370093 | X82: =(U82+V82) -> 472.09666
A83: Q4-2010 | B83: =SUM(C83:G83) -> 188966.9 | C83: 18909.4 | D83: 20018.2 | E83: 62600.9 | F83: 87438.4 | G83: ='1.Reel GSYH '!I80/'1.Reel GSYH '!$B80*100 -> 0.00070371114 | I83: ='1.Reel GSYH '!K80/'1.Reel GSYH '!$B80*100 -> 171.07035 | K83: ='1.Reel GSYH '!M80/'1.Reel GSYH '!$B80*100 -> 0 | L83: ='1.Reel GSYH '!N80/'1.Reel GSYH '!$B80*100 -> 0 | M83: ='1.Reel GSYH '!O80/'1.Reel GSYH '!$B80*100 -> 0 | N83: ='1.Reel GSYH '!P80/'1.Reel GSYH '!$B80*100 -> 0 | O83: ='1.Reel GSYH '!Q80/'1.Reel GSYH '!$B80*100 -> 0 | P83: ='1.Reel GSYH '!R80/'1.Reel GSYH '!$B80*100 -> 0 | Q83: ='1.Reel GSYH '!S80/'1.Reel GSYH '!$B80*100 -> 0 | S83: ='1.Reel GSYH '!U80/'1.Reel GSYH '!$B80*100 -> 0 | U83: ='1.Reel GSYH '!W80/'1.Reel GSYH '!$B80*100 -> 245.90924 | V83: ='1.Reel GSYH '!X80/'1.Reel GSYH '!$B80*100 -> 316.98101 | W83: ='1.Reel GSYH '!Y80/'1.Reel GSYH '!$B80*100 -> -71.071772 | X83: =(U83+V83) -> 562.89024
A84: Q1-2011 | B84: =SUM(C84:G84) -> 179730.6 | C84: 16529.5 | D84: 23137.9 | E84: 55977.4 | F84: 84085.8 | G84: ='1.Reel GSYH '!I81/'1.Reel GSYH '!$B81*100 -> 0.00087760477 | I84: ='1.Reel GSYH '!K81/'1.Reel GSYH '!$B81*100 -> 224.72948 | K84: ='1.Reel GSYH '!M81/'1.Reel GSYH '!$B81*100 -> 0 | L84: ='1.Reel GSYH '!N81/'1.Reel GSYH '!$B81*100 -> 0 | M84: ='1.Reel GSYH '!O81/'1.Reel GSYH '!$B81*100 -> 0 | N84: ='1.Reel GSYH '!P81/'1.Reel GSYH '!$B81*100 -> 0 | O84: ='1.Reel GSYH '!Q81/'1.Reel GSYH '!$B81*100 -> 0 | P84: ='1.Reel GSYH '!R81/'1.Reel GSYH '!$B81*100 -> 0 | Q84: ='1.Reel GSYH '!S81/'1.Reel GSYH '!$B81*100 -> 0 | S84: ='1.Reel GSYH '!U81/'1.Reel GSYH '!$B81*100 -> 0 | U84: ='1.Reel GSYH '!W81/'1.Reel GSYH '!$B81*100 -> 351.1071 | V84: ='1.Reel GSYH '!X81/'1.Reel GSYH '!$B81*100 -> 475.83834 | W84: ='1.Reel GSYH '!Y81/'1.Reel GSYH '!$B81*100 -> -124.73124 | X84: =(U84+V84) -> 826.94544
A85: Q2-2011 | B85: =SUM(C85:G85) -> 197761.7 | C85: 19098.9 | D85: 23366.5 | E85: 65328.2 | F85: 89968.1 | G85: ='1.Reel GSYH '!I82/'1.Reel GSYH '!$B82*100 -> 0.0010482506 | I85: ='1.Reel GSYH '!K82/'1.Reel GSYH '!$B82*100 -> 243.52717 | K85: ='1.Reel GSYH '!M82/'1.Reel GSYH '!$B82*100 -> 0 | L85: ='1.Reel GSYH '!N82/'1.Reel GSYH '!$B82*100 -> 0 | M85: ='1.Reel GSYH '!O82/'1.Reel GSYH '!$B82*100 -> 0 | N85: ='1.Reel GSYH '!P82/'1.Reel GSYH '!$B82*100 -> 0 | O85: ='1.Reel GSYH '!Q82/'1.Reel GSYH '!$B82*100 -> 0 | P85: ='1.Reel GSYH '!R82/'1.Reel GSYH '!$B82*100 -> 0 | Q85: ='1.Reel GSYH '!S82/'1.Reel GSYH '!$B82*100 -> 0 | S85: ='1.Reel GSYH '!U82/'1.Reel GSYH '!$B82*100 -> 0 | U85: ='1.Reel GSYH '!W82/'1.Reel GSYH '!$B82*100 -> 388.64906 | V85: ='1.Reel GSYH '!X82/'1.Reel GSYH '!$B82*100 -> 532.1783 | W85: ='1.Reel GSYH '!Y82/'1.Reel GSYH '!$B82*100 -> -143.52924 | X85: =(U85+V85) -> 920.82736
A86: Q3-2011 | B86: =SUM(C86:G86) -> 218127.4 | C86: 17801.8 | D86: 25012.9 | E86: 82795.9 | F86: 92516.8 | G86: ='1.Reel GSYH '!I83/'1.Reel GSYH '!$B83*100 -> 0.0011007333 | I86: ='1.Reel GSYH '!K83/'1.Reel GSYH '!$B83*100 -> 225.67216 | K86: ='1.Reel GSYH '!M83/'1.Reel GSYH '!$B83*100 -> 0 | L86: ='1.Reel GSYH '!N83/'1.Reel GSYH '!$B83*100 -> 0 | M86: ='1.Reel GSYH '!O83/'1.Reel GSYH '!$B83*100 -> 0 | N86: ='1.Reel GSYH '!P83/'1.Reel GSYH '!$B83*100 -> 0 | O86: ='1.Reel GSYH '!Q83/'1.Reel GSYH '!$B83*100 -> 0 | P86: ='1.Reel GSYH '!R83/'1.Reel GSYH '!$B83*100 -> 0 | Q86: ='1.Reel GSYH '!S83/'1.Reel GSYH '!$B83*100 -> 0 | S86: ='1.Reel GSYH '!U83/'1.Reel GSYH '!$B83*100 -> 0 | U86: ='1.Reel GSYH '!W83/'1.Reel GSYH '!$B83*100 -> 419.86753 | V86: ='1.Reel GSYH '!X83/'1.Reel GSYH '!$B83*100 -> 545.54184 | W86: ='1.Reel GSYH '!Y83/'1.Reel GSYH '!$B83*100 -> -125.67431 | X86: =(U86+V86) -> 965.40937
A87: Q4-2011 | B87: =SUM(C87:G87) -> 206757.2 | C87: 19788.6 | D87: 23775.3 | E87: 68534.6 | F87: 94658.7 | G87: ='1.Reel GSYH '!I84/'1.Reel GSYH '!$B84*100 -> 0.00081169531 | I87: ='1.Reel GSYH '!K84/'1.Reel GSYH '!$B84*100 -> 184.4569 | K87: ='1.Reel GSYH '!M84/'1.Reel GSYH '!$B84*100 -> 0 | L87: ='1.Reel GSYH '!N84/'1.Reel GSYH '!$B84*100 -> 0 | M87: ='1.Reel GSYH '!O84/'1.Reel GSYH '!$B84*100 -> 0 | N87: ='1.Reel GSYH '!P84/'1.Reel GSYH '!$B84*100 -> 0 | O87: ='1.Reel GSYH '!Q84/'1.Reel GSYH '!$B84*100 -> 0 | P87: ='1.Reel GSYH '!R84/'1.Reel GSYH '!$B84*100 -> 0 | Q87: ='1.Reel GSYH '!S84/'1.Reel GSYH '!$B84*100 -> 0 | S87: ='1.Reel GSYH '!U84/'1.Reel GSYH '!$B84*100 -> 0 | U87: ='1.Reel GSYH '!W84/'1.Reel GSYH '!$B84*100 -> 320.46067 | V87: ='1.Reel GSYH '!X84/'1.Reel GSYH '!$B84*100 -> 404.91913 | W87: ='1.Reel GSYH '!Y84/'1.Reel GSYH '!$B84*100 -> -84.458457 | X87: =(U87+V87) -> 725.37981
A88: Q1-2012 | B88: =SUM(C88:G88) -> 186509.3 | C88: 15596.4 | D88: 24269.3 | E88: 61055.8 | F88: 85587.8 | G88: ='1.Reel GSYH '!I85/'1.Reel GSYH '!$B85*100 -> 0.0007042087 | I88: ='1.Reel GSYH '!K85/'1.Reel GSYH '!$B85*100 -> 175.48173 | K88: ='1.Reel GSYH '!M85/'1.Reel GSYH '!$B85*100 -> 0 | L88: ='1.Reel GSYH '!N85/'1.Reel GSYH '!$B85*100 -> 0 | M88: ='1.Reel GSYH '!O85/'1.Reel GSYH '!$B85*100 -> 0 | N88: ='1.Reel GSYH '!P85/'1.Reel GSYH '!$B85*100 -> 0 | O88: ='1.Reel GSYH '!Q85/'1.Reel GSYH '!$B85*100 -> 0 | P88: ='1.Reel GSYH '!R85/'1.Reel GSYH '!$B85*100 -> 0 | Q88: ='1.Reel GSYH '!S85/'1.Reel GSYH '!$B85*100 -> 0 | S88: ='1.Reel GSYH '!U85/'1.Reel GSYH '!$B85*100 -> 0 | U88: ='1.Reel GSYH '!W85/'1.Reel GSYH '!$B85*100 -> 304.91691 | V88: ='1.Reel GSYH '!X85/'1.Reel GSYH '!$B85*100 -> 380.39998 | W88: ='1.Reel GSYH '!Y85/'1.Reel GSYH '!$B85*100 -> -75.48307 | X88: =(U88+V88) -> 685.31688
... A106: Q3-2016 | B106: =SUM(C106:G106) -> 253664.6 | C106: 23443 | D106: 25604.2 | E106: 90550.4 | F106: 114067 | G106: ='1.Reel GSYH '!I103/'1.Reel GSYH '!$B103*100 -> 0.00048219995 | I106: ='1.Reel GSYH '!K103/'1.Reel GSYH '!$B103*100 -> 119.22321 | K106: ='1.Reel GSYH '!M103/'1.Reel GSYH '!$B103*100 -> 0 | L106: ='1.Reel GSYH '!N103/'1.Reel GSYH '!$B103*100 -> 0 | M106: ='1.Reel GSYH '!O103/'1.Reel GSYH '!$B103*100 -> 0 | N106: ='1.Reel GSYH '!P103/'1.Reel GSYH '!$B103*100 -> 0 | O106: ='1.Reel GSYH '!Q103/'1.Reel GSYH '!$B103*100 -> 0 | P106: ='1.Reel GSYH '!R103/'1.Reel GSYH '!$B103*100 -> 0 | Q106: ='1.Reel GSYH '!S103/'1.Reel GSYH '!$B103*100 -> 0 | S106: ='1.Reel GSYH '!U103/'1.Reel GSYH '!$B103*100 -> 0 | U106: ='1.Reel GSYH '!W103/'1.Reel GSYH '!$B103*100 -> 176.90826 | V106: ='1.Reel GSYH '!X103/'1.Reel GSYH '!$B103*100 -> 196.13228 | W106: ='1.Reel GSYH '!Y103/'1.Reel GSYH '!$B103*100 -> -19.224018 | X106: =(U106+V106) -> 373.04054
A109: Ortalamalar
A110: 1998-2001 | B110: =AVERAGE(B32:B47) -> #DIV/0! | C110: =AVERAGE(C32:C47) -> #DIV/0! | D110: =AVERAGE(D32:D47) -> #DIV/0! | E110: =AVERAGE(E32:E47) -> #DIV/0! | F110: =AVERAGE(F32:F47) -> #DIV/0! | G110: =AVERAGE(G32:G47) -> #DIV/0! | I110: =AVERAGE(I32:I47) -> #DIV/0! | K110: =AVERAGE(K32:K47) -> #DIV/0! | L110: =AVERAGE(L32:L47) -> #DIV/0! | M110: =AVERAGE(M32:M47) -> #DIV/0! | N110: =AVERAGE(N32:N47) -> #DIV/0! | O110: =AVERAGE(O32:O47) -> #DIV/0! | P110: =AVERAGE(P32:P47) -> #DIV/0! | Q110: =AVERAGE(Q32:Q47) -> #DIV/0! | S110: =AVERAGE(S32:S47) -> #DIV/0! | U110: =AVERAGE(U32:U47) -> #DIV/0! | V110: =AVERAGE(V32:V47) -> #DIV/0! | W110: =AVERAGE(W32:W47) -> #DIV/0! | X110: =AVERAGE(X32:X47) -> #DIV/0!
A111: 2002-2005 | B111: =AVERAGE(B48:B63) -> #DIV/0! | C111: =AVERAGE(C48:C63) -> #DIV/0! | D111: =AVERAGE(D48:D63) -> #DIV/0! | E111: =AVERAGE(E48:E63) -> #DIV/0! | F111: =AVERAGE(F48:F63) -> #DIV/0! | G111: =AVERAGE(G48:G63) -> #DIV/0! | I111: =AVERAGE(I48:I63) -> #DIV/0! | K111: =AVERAGE(K48:K63) -> #DIV/0! | L111: =AVERAGE(L48:L63) -> #DIV/0! | M111: =AVERAGE(M48:M63) -> #DIV/0! | N111: =AVERAGE(N48:N63) -> #DIV/0! | O111: =AVERAGE(O48:O63) -> #DIV/0! | P111: =AVERAGE(P48:P63) -> #DIV/0! | Q111: =AVERAGE(Q48:Q63) -> #DIV/0! | S111: =AVERAGE(S48:S63) -> #DIV/0! | U111: =AVERAGE(U48:U63) -> #DIV/0! | V111: =AVERAGE(V48:V63) -> #DIV/0! | W111: =AVERAGE(W48:W63) -> #DIV/0! | X111: =AVERAGE(X48:X63) -> #DIV/0!
A112: 2006-2009 | B112: =AVERAGE(B64:B79) -> #DIV/0! | C112: =AVERAGE(C64:C79) -> #DIV/0! | D112: =AVERAGE(D64:D79) -> #DIV/0! | E112: =AVERAGE(E64:E79) -> #DIV/0! | F112: =AVERAGE(F64:F79) -> #DIV/0! | G112: =AVERAGE(G64:G79) -> #DIV/0! | I112: =AVERAGE(I64:I79) -> #DIV/0! | K112: =AVERAGE(K64:K79) -> #DIV/0! | L112: =AVERAGE(L64:L79) -> #DIV/0! | M112: =AVERAGE(M64:M79) -> #DIV/0! | N112: =AVERAGE(N64:N79) -> #DIV/0! | O112: =AVERAGE(O64:O79) -> #DIV/0! | P112: =AVERAGE(P64:P79) -> #DIV/0! | Q112: =AVERAGE(Q64:Q79) -> #DIV/0! | S112: =AVERAGE(S64:S79) -> #DIV/0! | U112: =AVERAGE(U64:U79) -> #DIV/0! | V112: =AVERAGE(V64:V79) -> #DIV/0! | W112: =AVERAGE(W64:W79) -> #DIV/0! | X112: =AVERAGE(X64:X79) -> #DIV/0!
...

Sheet 1b. Reel GSYH Pay Grafikleri
B1: Ülke Analizi
B2: Toplam Talep Analizi
B3: GSYH unsurlarının payı

Sheet 1c. Büyümeye Katkı
B1: Ülke Analizi
B2: Toplam Talep Analizi
B3: GSYH Büyümesine Katkı
K10: =(D17/D13-1)*100 | L10: =(E17/E13-1)*100 | M10: =(F17/F13-1)*100 | N10: =(G17/G13-1)*100 | O10: =(H17/H13-1)*100 | P10: =(I17/I13-1)*100 | R10: =(B17/B13-1)*100 | T10: =((D17-D13)/($B13))*100 | Y10: =((I17-I13)/($B13))*100
D11: GSYH Bileşenleri (Düzey, 2008 Fiyatları-DND Milyar) | K11: GSYH Bileşenlerinin Büyüme Oranları | T11: Reel GSYH Büyümesi Katkı ( Yıllık)
B12: Reel GSYH (Düzey, 2008 Fiyatları-DND Milyar) | D12: Özel Tüketim (Cp) | E12: Kamu Tüketimi (Cg) | F12: Kamu GFCF (Ig) | G12: Özel GFCF (Ip) | H12: Stok Değişimi (Ip) | I12: Net İhracat (NX) | K12: Özel Tüketim (Cp) | L12: Kamu Tüketimi (Cg) | M12: Kamu GFCF (Ig) | N12: Özel GFCF (Ip) | O12: Stok Değişimi (Ip) | P12: Net İhracat (NX) | R12: Reel GSYH Büyüme Oranı( yıllık % değişim) | T12: Özel Tüketimin (Cp) Büyümeye Katkısı | U12: Kamu Tüketiminin (Cg) Büyümeye Katkısı | V12: Kamu Yatırımının (Ig) Büyümeye Katkısı | W12: Özel Yatırımın (Ip) Büyümeye Katkısı | X12: Stok Değişiminin Büyümeye Katkısı | Y12: Net İhracatın (NX) Büyümeye Katkısı
A13: Q1-1993 | B13: ='1.Reel GSYH '!B9 -> 0 | D13: ='1.Reel GSYH '!D9 -> 0 | E13: ='1.Reel GSYH '!K9 -> 0 | F13: ='1.Reel GSYH '!N9 -> 0 | G13: ='1.Reel GSYH '!Q9 -> 0 | H13: ='1.Reel GSYH '!U9 -> 23.293625 | I13: ='1.Reel GSYH '!Y9 -> 0
A14: Q2-1993 | B14: ='1.Reel GSYH '!B10 -> 0 | D14: ='1.Reel GSYH '!D10 -> 0 | E14: ='1.Reel GSYH '!K10 -> 0 | F14: ='1.Reel GSYH '!N10 -> 0 | G14: ='1.Reel GSYH '!Q10 -> 0 | H14: ='1.Reel GSYH '!U10 -> 29.357175 | I14: ='1.Reel GSYH '!Y10 -> 0
A15: Q3-1993 | B15: ='1.Reel GSYH '!B11 -> 0 | D15: ='1.Reel GSYH '!D11 -> 0 | E15: ='1.Reel GSYH '!K11 -> 0 | F15: ='1.Reel GSYH '!N11 -> 0 | G15: ='1.Reel GSYH '!Q11 -> 0 | H15: ='1.Reel GSYH '!U11 -> 18.210875 | I15: ='1.Reel GSYH '!Y11 -> 0
A16: Q4-1993 | B16: ='1.Reel GSYH '!B12 -> 0 | D16: ='1.Reel GSYH '!D12 -> 0 | E16: ='1.Reel GSYH '!K12 -> 0 | F16: ='1.Reel GSYH '!N12 -> 0 | G16: ='1.Reel GSYH '!Q12 -> 0 | H16: ='1.Reel GSYH '!U12 -> 9.5901 | I16: ='1.Reel GSYH '!Y12 -> 0
A17: Q1-1994 | B17: ='1.Reel GSYH '!B13 -> 0 | D17: ='1.Reel GSYH '!D13 -> 0 | E17: ='1.Reel GSYH '!K13 -> 0 | F17: ='1.Reel GSYH '!N13 -> 0 | G17: ='1.Reel GSYH '!Q13 -> 0 | H17: ='1.Reel GSYH '!U13 -> 15.654625 | I17: ='1.Reel GSYH '!Y13 -> 0 | U17: =((E17-E13)/($B13))*100 -> #DIV/0! | V17: =((F17-F13)/($B13))*100 -> #DIV/0! | W17: =((G17-G13)/($B13))*100 -> #DIV/0! | X17: =((H17-H13)/($B13))*100 -> #DIV/0!
A18: Q2-1994 | B18: ='1.Reel GSYH '!B14 -> 0 | D18: ='1.Reel GSYH '!D14 -> 0 | E18: ='1.Reel GSYH '!K14 -> 0 | F18: ='1.Reel GSYH '!N14 -> 0 | G18: ='1.Reel GSYH '!Q14 -> 0 | H18: ='1.Reel GSYH '!U14 -> 39.951925 | I18: ='1.Reel GSYH '!Y14 -> 0 | U18: =((E18-E14)/($B14))*100 -> #DIV/0! | V18: =((F18-F14)/($B14))*100 -> #DIV/0! | W18: =((G18-G14)/($B14))*100 -> #DIV/0! | X18: =((H18-H14)/($B14))*100 -> #DIV/0!
A19: Q3-1994 | B19: ='1.Reel GSYH '!B15 -> 0 | D19: ='1.Reel GSYH '!D15 -> 0 | E19: ='1.Reel GSYH '!K15 -> 0 | F19: ='1.Reel GSYH '!N15 -> 0 | G19: ='1.Reel GSYH '!Q15 -> 0 | H19: ='1.Reel GSYH '!U15 -> 19.97175 | I19: ='1.Reel GSYH '!Y15 -> 0 | U19: =((E19-E15)/($B15))*100 -> #DIV/0! | V19: =((F19-F15)/($B15))*100 -> #DIV/0! | W19: =((G19-G15)/($B15))*100 -> #DIV/0! | X19: =((H19-H15)/($B15))*100 -> #DIV/0!
A20: Q4-1994 | B20: ='1.Reel GSYH '!B16 -> 0 | D20: ='1.Reel GSYH '!D16 -> 0 | E20: ='1.Reel GSYH '!K16 -> 0 | F20: ='1.Reel GSYH '!N16 -> 0 | G20: ='1.Reel GSYH '!Q16 -> 0 | H20: ='1.Reel GSYH '!U16 -> 24.088725 | I20: ='1.Reel GSYH '!Y16 -> 0 | U20: =((E20-E16)/($B16))*100 -> #DIV/0! | V20: =((F20-F16)/($B16))*100 -> #DIV/0! | W20: =((G20-G16)/($B16))*100 -> #DIV/0! | X20: =((H20-H16)/($B16))*100 -> #DIV/0!
A21: Q1-1995 | B21: ='1.Reel GSYH '!B17 -> 0 | D21: ='1.Reel GSYH '!D17 -> 0 | E21: ='1.Reel GSYH '!K17 -> 0 | F21: ='1.Reel GSYH '!N17 -> 0 | G21: ='1.Reel GSYH '!Q17 -> 0 | H21: ='1.Reel GSYH '!U17 -> 26.944575 | I21: ='1.Reel GSYH '!Y17 -> 0 | U21: =((E21-E17)/($B17))*100 -> #DIV/0! | V21: =((F21-F17)/($B17))*100 -> #DIV/0! | W21: =((G21-G17)/($B17))*100 -> #DIV/0! | X21: =((H21-H17)/($B17))*100 -> #DIV/0!
A22: Q2-1995 | B22: ='1.Reel GSYH '!B18 -> 0 | D22: ='1.Reel GSYH '!D18 -> 0 | E22: ='1.Reel GSYH '!K18 -> 0 | F22: ='1.Reel GSYH '!N18 -> 0 | G22: ='1.Reel GSYH '!Q18 -> 0 | H22: ='1.Reel GSYH '!U18 -> 26.403175 | I22: ='1.Reel GSYH '!Y18 -> 0 | U22: =((E22-E18)/($B18))*100 -> #DIV/0! | V22: =((F22-F18)/($B18))*100 -> #DIV/0! | W22: =((G22-G18)/($B18))*100 -> #DIV/0! | X22: =((H22-H18)/($B18))*100 -> #DIV/0!
A23: Q3-1995 | B23: ='1.Reel GSYH '!B19 -> 0 | D23: ='1.Reel GSYH '!D19 -> 0 | E23: ='1.Reel GSYH '!K19 -> 0 | F23: ='1.Reel GSYH '!N19 -> 0 | G23: ='1.Reel GSYH '!Q19 -> 0 | H23: ='1.Reel GSYH '!U19 -> 35.6198 | I23: ='1.Reel GSYH '!Y19 -> 0 | U23: =((E23-E19)/($B19))*100 -> #DIV/0! | V23: =((F23-F19)/($B19))*100 -> #DIV/0! | W23: =((G23-G19)/($B19))*100 -> #DIV/0! | X23: =((H23-H19)/($B19))*100 -> #DIV/0!
A24: Q4-1995 | B24: ='1.Reel GSYH '!B20 -> 0 | D24: ='1.Reel GSYH '!D20 -> 0 | E24: ='1.Reel GSYH '!K20 -> 0 | F24: ='1.Reel GSYH '!N20 -> 0 | G24: ='1.Reel GSYH '!Q20 -> 0 | H24: ='1.Reel GSYH '!U20 -> 41.673575 | I24: ='1.Reel GSYH '!Y20 -> 0 | U24: =((E24-E20)/($B20))*100 -> #DIV/0! | V24: =((F24-F20)/($B20))*100 -> #DIV/0! | W24: =((G24-G20)/($B20))*100 -> #DIV/0! | X24: =((H24-H20)/($B20))*100 -> #DIV/0!
A25: Q1-1996 | B25: ='1.Reel GSYH '!B21 -> 0 | D25: ='1.Reel GSYH '!D21 -> 0 | E25: ='1.Reel GSYH '!K21 -> 0 | F25: ='1.Reel GSYH '!N21 -> 0 | G25: ='1.Reel GSYH '!Q21 -> 0 | H25: ='1.Reel GSYH '!U21 -> 43.87125 | I25: ='1.Reel GSYH '!Y21 -> 0 | U25: =((E25-E21)/($B21))*100 -> #DIV/0! | V25: =((F25-F21)/($B21))*100 -> #DIV/0! | W25: =((G25-G21)/($B21))*100 -> #DIV/0! | X25: =((H25-H21)/($B21))*100 -> #DIV/0!
A26: Q2-1996 | B26: ='1.Reel GSYH '!B22 -> 0 | D26: ='1.Reel GSYH '!D22 -> 0 | E26: ='1.Reel GSYH '!K22 -> 0 | F26: ='1.Reel GSYH '!N22 -> 0 | G26: ='1.Reel GSYH '!Q22 -> 0 | H26: ='1.Reel GSYH '!U22 -> 39.57155 | I26: ='1.Reel GSYH '!Y22 -> 0 | U26: =((E26-E22)/($B22))*100 -> #DIV/0! | V26: =((F26-F22)/($B22))*100 -> #DIV/0! | W26: =((G26-G22)/($B22))*100 -> #DIV/0! | X26: =((H26-H22)/($B22))*100 -> #DIV/0!
A27: Q3-1996 | B27: ='1.Reel GSYH '!B23 -> 0 | D27: ='1.Reel GSYH '!D23 -> 0 | E27: ='1.Reel GSYH '!K23 -> 0 | F27: ='1.Reel GSYH '!N23 -> 0 | G27: ='1.Reel GSYH '!Q23 -> 0 | H27: ='1.Reel GSYH '!U23 -> 48.869275 | I27: ='1.Reel GSYH '!Y23 -> 0 | U27: =((E27-E23)/($B23))*100 -> #DIV/0! | V27: =((F27-F23)/($B23))*100 -> #DIV/0! | W27: =((G27-G23)/($B23))*100 -> #DIV/0! | X27: =((H27-H23)/($B23))*100 -> #DIV/0!
A28: Q4-1996 | B28: ='1.Reel GSYH '!B24 -> 0 | D28: ='1.Reel GSYH '!D24 -> 0 | E28: ='1.Reel GSYH '!K24 -> 0 | F28: ='1.Reel GSYH '!N24 -> 0 | G28: ='1.Reel GSYH '!Q24 -> 0 | H28: ='1.Reel GSYH '!U24 -> 48.701525 | I28: ='1.Reel GSYH '!Y24 -> 0 | U28: =((E28-E24)/($B24))*100 -> #DIV/0! | V28: =((F28-F24)/($B24))*100 -> #DIV/0! | W28: =((G28-G24)/($B24))*100 -> #DIV/0! | X28: =((H28-H24)/($B24))*100 -> #DIV/0!
... A76: Q4-2008 | B76: ='1.Reel GSYH '!B72 -> 0 | D76: ='1.Reel GSYH '!D72 -> 0 | E76: ='1.Reel GSYH '!K72 -> 34531531990 | F76: ='1.Reel GSYH '!N72 -> 0 | G76: ='1.Reel GSYH '!Q72 -> 0 | H76: ='1.Reel GSYH '!U72 -> 0 | I76: ='1.Reel GSYH '!Y72 -> -2622701490 | U76: =((E76-E72)/($B72))*100 -> #DIV/0! | V76: =((F76-F72)/($B72))*100 -> #DIV/0! | W76: =((G76-G72)/($B72))*100 -> #DIV/0! | X76: =((H76-H72)/($B72))*100 -> #DIV/0!
A77: Q1-2009 | B77: ='1.Reel GSYH '!B73 -> 4.1711555e+10 | D77: ='1.Reel GSYH '!D73 -> 273435.7 | E77: ='1.Reel GSYH '!K73 -> 37205453390 | F77: ='1.Reel GSYH '!N73 -> 0 | G77: ='1.Reel GSYH '!Q73 -> 0 | H77: ='1.Reel GSYH '!U73 -> 0 | I77: ='1.Reel GSYH '!Y73 -> 4505827700 | K77: =(D81/D77-1)*100 -> 9.7383041 | P77: =(I81/I77-1)*100 -> -268.77084 | R77: =R81 -> -39.337968 | T77: =((D81-D77)/($B77))*100 -> 6.3838426e-05 | U77: =((E77-E73)/($B73))*100 -> #DIV/0! | V77: =((F77-F73)/($B73))*100 -> #DIV/0! | W77: =((G77-G73)/($B73))*100 -> #DIV/0! | X77: =((H77-H73)/($B73))*100 -> #DIV/0!
A78: Q2-2009 | B78: ='1.Reel GSYH '!B74 -> 3.7452284e+10 | D78: ='1.Reel GSYH '!D74 -> 303049.9 | E78: ='1.Reel GSYH '!K74 -> 38245187990 | F78: ='1.Reel GSYH '!N74 -> 0 | G78: ='1.Reel GSYH '!Q74 -> 0 | H78: ='1.Reel GSYH '!U74 -> 0 | I78: ='1.Reel GSYH '!Y74 -> -793206780 | K78: =(D82/D78-1)*100 -> 11.734305 | P78: =(I82/I78-1)*100 -> 1010.5917 | R78: =(B82/B78-1)*100 -> -9.7033246 | T78: =((D82-D78)/($B78))*100 -> 9.4949616e-05 | U78: =((E78-E74)/($B74))*100 -> #DIV/0! | V78: =((F78-F74)/($B74))*100 -> #DIV/0! | W78: =((G78-G74)/($B74))*100 -> #DIV/0! | X78: =((H78-H74)/($B74))*100 -> #DIV/0!
A79: Q3-2009 | B79: ='1.Reel GSYH '!B75 -> 3.8455469e+10 | D79: ='1.Reel GSYH '!D75 -> 340495.8 | E79: ='1.Reel GSYH '!K75 -> 39645740940 | F79: ='1.Reel GSYH '!N75 -> 0 | G79: ='1.Reel GSYH '!Q75 -> 0 | H79: ='1.Reel GSYH '!U75 -> 0 | I79: ='1.Reel GSYH '!Y75 -> -1190612180 | K79: =(D83/D79-1)*100 -> 15.764159 | P79: =(I83/I79-1)*100 -> 1166.196 | R79: =(B83/B79-1)*100 -> -23.686254 | T79: =((D83-D79)/($B79))*100 -> 0.00013958041 | U79: =((E79-E75)/($B75))*100 -> #DIV/0! | V79: =((F79-F75)/($B75))*100 -> #DIV/0! | W79: =((G79-G75)/($B75))*100 -> #DIV/0! | X79: =((H79-H75)/($B75))*100 -> #DIV/0!
A80: Q4-2009 | B80: ='1.Reel GSYH '!B76 -> 3.9488665e+10 | D80: ='1.Reel GSYH '!D76 -> 328447.9 | E80: ='1.Reel GSYH '!K76 -> 42480006080 | F80: ='1.Reel GSYH '!N76 -> 0 | G80: ='1.Reel GSYH '!Q76 -> 0 | H80: ='1.Reel GSYH '!U76 -> 0 | I80: ='1.Reel GSYH '!Y76 -> -2991669250 | K80: =(D84/D80-1)*100 -> 14.185781 | P80: =(I84/I80-1)*100 -> 528.16625 | R80: =(B84/B80-1)*100 -> -33.039517 | T80: =((D84-D80)/($B80))*100 -> 0.00011799057 | U80: =((E80-E76)/($B76))*100 -> #DIV/0! | V80: =((F80-F76)/($B76))*100 -> #DIV/0! | W80: =((G80-G76)/($B76))*100 -> #DIV/0! | X80: =((H80-H76)/($B76))*100 -> #DIV/0!
A81: Q1-2010 | B81: ='1.Reel GSYH '!B77 -> 3.3797608e+10 | D81: ='1.Reel GSYH '!D77 -> 300063.7 | E81: ='1.Reel GSYH '!K77 -> 41401830940 | F81: ='1.Reel GSYH '!N77 -> 0 | G81: ='1.Reel GSYH '!Q77 -> 0 | H81: ='1.Reel GSYH '!U77 -> 0 | I81: ='1.Reel GSYH '!Y77 -> -7.6045231e+09 | K81: =(D85/D81-1)*100 -> 19.861183 | P81: =(I85/I81-1)*100 -> 236.28397 | R81: =(B85/B81-1)*100 -> -39.337968 | T81: =((D85-D81)/($B81))*100 -> 0.0001763326 | U81: =((E81-E77)/($B77))*100 -> 10.060468 | V81: =((F81-F77)/($B77))*100 -> 0 | W81: =((G81-G77)/($B77))*100 -> 0 | X81: =((H81-H77)/($B77))*100 -> 0 | Y81: =((I85-I81)/($B81))*100 -> -53.164322
A82: Q2-2010 | B82: ='1.Reel GSYH '!B78 -> 3.3818168e+10 | D82: ='1.Reel GSYH '!D78 -> 338610.7 | E82: ='1.Reel GSYH '!K78 -> 42627117410 | F82: ='1.Reel GSYH '!N78 -> 0 | G82: ='1.Reel GSYH '!Q78 -> 0 | H82: ='1.Reel GSYH '!U78 -> 0 | I82: ='1.Reel GSYH '!Y78 -> -8809288490 | K82: =(D86/D82-1)*100 -> 18.117531 | P82: =(I86/I82-1)*100 -> 214.27436 | R82: =(B86/B82-1)*100 -> -42.962652 | T82: =((D86-D82)/($B82))*100 -> 0.00018140516 | U82: =((E82-E78)/($B78))*100 -> 11.700032 | V82: =((F82-F78)/($B78))*100 -> 0 | W82: =((G82-G78)/($B78))*100 -> 0 | X82: =((H82-H78)/($B78))*100 -> 0 | Y82: =((I86-I82)/($B82))*100 -> -55.81629
A83: Q3-2010 | B83: ='1.Reel GSYH '!B79 -> 2.9346809e+10 | D83: ='1.Reel GSYH '!D79 -> 394172.1 | E83: ='1.Reel GSYH '!K79 -> 44421898300 | F83: ='1.Reel GSYH '!N79 -> 0 | G83: ='1.Reel GSYH '!Q79 -> 0 | H83: ='1.Reel GSYH '!U79 -> 0 | I83: ='1.Reel GSYH '!Y79 -> -15075483250 | K83: =(D87/D83-1)*100 -> 13.492558 | P83: =(I87/I83-1)*100 -> 73.60489 | R83: =(B87/B83-1)*100 -> -29.038008 | T83: =((D87-D83)/($B83))*100 -> 0.00018122549 | U83: =((E83-E79)/($B79))*100 -> 12.419969 | V83: =((F83-F79)/($B79))*100 -> 0 | W83: =((G83-G79)/($B79))*100 -> 0 | X83: =((H83-H79)/($B79))*100 -> 0 | Y83: =((I87-I83)/($B83))*100 -> -37.810901
A84: Q4-2010 | B84: ='1.Reel GSYH '!B80 -> 2.6441801e+10 | D84: ='1.Reel GSYH '!D80 -> 375040.8 | E84: ='1.Reel GSYH '!K80 -> 45234082450 | F84: ='1.Reel GSYH '!N80 -> 0 | G84: ='1.Reel GSYH '!Q80 -> 0 | H84: ='1.Reel GSYH '!U80 -> 0 | I84: ='1.Reel GSYH '!Y80 -> -18792656570 | K84: =(D88/D84-1)*100 -> 15.004288 | P84: =(I88/I84-1)*100 -> 24.332941 | R84: =(B88/B84-1)*100 -> 4.6261411 | T84: =((D88-D84)/($B84))*100 -> 0.00021281531 | U84: =((E84-E80)/($B80))*100 -> 6.9743466 | V84: =((F84-F80)/($B80))*100 -> 0 | W84: =((G84-G80)/($B80))*100 -> 0 | X84: =((H84-H80)/($B80))*100 -> 0 | Y84: =((I88-I84)/($B84))*100 -> -17.293852
A85: Q1-2011 | B85: ='1.Reel GSYH '!B81 -> 2.0502316e+10 | D85: ='1.Reel GSYH '!D81 -> 359659.9 | E85: ='1.Reel GSYH '!K81 -> 46074748340 | F85: ='1.Reel GSYH '!N81 -> 0 | G85: ='1.Reel GSYH '!Q81 -> 0 | H85: ='1.Reel GSYH '!U81 -> 0 | I85: ='1.Reel GSYH '!Y81 -> -25572792340 | K85: =(D89/D85-1)*100 -> 8.9517903 | P85: =(I89/I85-1)*100 -> -13.928865 | R85: =(B89/B85-1)*100 -> 42.227381 | T85: =((D89-D85)/($B85))*100 -> 0.00015703592 | U85: =((E85-E81)/($B81))*100 -> 13.826178 | V85: =((F85-F81)/($B81))*100 -> 0 | W85: =((G85-G81)/($B81))*100 -> 0 | X85: =((H85-H81)/($B81))*100 -> 0 | Y85: =((I89-I85)/($B85))*100 -> 17.373646
A86: Q2-2011 | B86: ='1.Reel GSYH '!B82 -> 1.9288986e+10 | D86: ='1.Reel GSYH '!D82 -> 399958.6 | E86: ='1.Reel GSYH '!K82 -> 46973920890 | F86: ='1.Reel GSYH '!N82 -> 0 | G86: ='1.Reel GSYH '!Q82 -> 0 | H86: ='1.Reel GSYH '!U82 -> 0 | I86: ='1.Reel GSYH '!Y82 -> -27685335060 | K86: =(D90/D86-1)*100 -> 7.4670728 | P86: =(I90/I86-1)*100 -> -41.229861 | R86: =(B90/B86-1)*100 -> 106.89095 | T86: =((D90-D86)/($B86))*100 -> 0.00015483033 | U86: =((E86-E82)/($B82))*100 -> 12.853457 | V86: =((F86-F82)/($B82))*100 -> 0 | W86: =((G86-G82)/($B82))*100 -> 0 | X86: =((H86-H82)/($B82))*100 -> 0 | Y86: =((I90-I86)/($B86))*100 -> 59.176907
A87: Q3-2011 | B87: ='1.Reel GSYH '!B83 -> 20825080286 | D87: ='1.Reel GSYH '!D83 -> 447356 | E87: ='1.Reel GSYH '!K83 -> 46996409100 | F87: ='1.Reel GSYH '!N83 -> 0 | G87: ='1.Reel GSYH '!Q83 -> 0 | H87: ='1.Reel GSYH '!U83 -> 0 | I87: ='1.Reel GSYH '!Y83 -> -26171776170 | K87: =(D91/D87-1)*100 -> 6.8593246 | P87: =(I91/I87-1)*100 -> -41.750883 | R87: =(B91/B87-1)*100 -> 104.46611 | T87: =((D91-D87)/($B87))*100 -> 0.00014734925 | U87: =((E87-E83)/($B83))*100 -> 8.7727111 | V87: =((F87-F83)/($B83))*100 -> 0 | W87: =((G87-G83)/($B83))*100 -> 0 | X87: =((H87-H83)/($B83))*100 -> 0 | Y87: =((I91-I87)/($B87))*100 -> 52.470134
A88: Q4-2011 | B88: ='1.Reel GSYH '!B84 -> 27665035933 | D88: ='1.Reel GSYH '!D84 -> 431313 | E88: ='1.Reel GSYH '!K84 -> 51030067210 | F88: ='1.Reel GSYH '!N84 -> 0 | G88: ='1.Reel GSYH '!Q84 -> 0 | H88: ='1.Reel GSYH '!U84 -> 0 | I88: ='1.Reel GSYH '!Y84 -> -23365462590 | K88: =(D92/D88-1)*100 -> 7.6557164 | P88: =(I92/I88-1)*100 -> -50.964089 | R88: =(B92/B88-1)*100 -> 69.066699 | T88: =((D92-D88)/($B88))*100 -> 0.00011935679 | U88: =((E88-E84)/($B84))*100 -> 21.919781 | V88: =((F88-F84)/($B84))*100 -> 0 | W88: =((G88-G84)/($B84))*100 -> 0 | X88: =((H88-H84)/($B84))*100 -> 0 | Y88: =((I92-I88)/($B88))*100 -> 43.043483
A89: Q1-2012 | B89: ='1.Reel GSYH '!B85 -> 2.9159907e+10 | D89: ='1.Reel GSYH '!D85 -> 391855.9 | E89: ='1.Reel GSYH '!K85 -> 51170307400 | F89: ='1.Reel GSYH '!N85 -> 0 | G89: ='1.Reel GSYH '!Q85 -> 0 | H89: ='1.Reel GSYH '!U85 -> 0 | I89: ='1.Reel GSYH '!Y85 -> -22010792620 | K89: =(D93/D89-1)*100 -> 9.8716901 | P89: =(I93/I89-1)*100 -> -2.0730709 | R89: =(B93/B89-1)*100 -> 36.608636 | T89: =((D93-D89)/($B89))*100 -> 0.00013265749 | U89: =((E89-E85)/($B85))*100 -> 24.853578 | V89: =((F89-F85)/($B85))*100 -> 0 | W89: =((G89-G85)/($B85))*100 -> 0 | X89: =((H89-H85)/($B85))*100 -> 0 | Y89: =((I93-I89)/($B89))*100 -> 1.5648176
A90: Q2-2012 | B90: ='1.Reel GSYH '!B86 -> 3.9907166e+10 | D90: ='1.Reel GSYH '!D86 -> 429823.8 | E90: ='1.Reel GSYH '!K86 -> 56177446370 | F90: ='1.Reel GSYH '!N86 -> 0 | G90: ='1.Reel GSYH '!Q86 -> 0 | H90: ='1.Reel GSYH '!U86 -> 0 | I90: ='1.Reel GSYH '!Y86 -> -16270709960 | K90: =(D94/D90-1)*100 -> 11.446877 | P90: =(I94/I90-1)*100 -> 30.463479 | R90: =(B94/B90-1)*100 -> 3.8428791 | T90: =((D94-D90)/($B90))*100 -> 0.00012328964 | U90: =((E90-E86)/($B86))*100 -> 47.71389 | V90: =((F90-F86)/($B86))*100 -> 0 | W90: =((G90-G86)/($B86))*100 -> 0 | X90: =((H90-H86)/($B86))*100 -> 0 | Y90: =((I94-I90)/($B90))*100 -> -12.420386
A91: Q3-2012 | B91: ='1.Reel GSYH '!B87 -> 4.2580232e+10 | D91: ='1.Reel GSYH '!D87 -> 478041.6 | E91: ='1.Reel GSYH '!K87 -> 57824582560 | F91: ='1.Reel GSYH '!N87 -> 0 | G91: ='1.Reel GSYH '!Q87 -> 0 | H91: ='1.Reel GSYH '!U87 -> 0 | I91: ='1.Reel GSYH '!Y87 -> -15244828560 | K91: =(D95/D91-1)*100 -> 11.562948 | P91: =(I95/I91-1)*100 -> 55.404657 | R91: =(B95/B91-1)*100 -> -1.0774464 | T91: =((D95-D91)/($B91))*100 -> 0.0001298154 | U91: =((E91-E87)/($B87))*100 -> 51.995831 | V91: =((F91-F87)/($B87))*100 -> 0 | W91: =((G91-G87)/($B87))*100 -> 0 | X91: =((H91-H87)/($B87))*100 -> 0 | Y91: =((I95-I91)/($B91))*100 -> -19.836306
A92: Q4-2012 | B92: ='1.Reel GSYH '!B88 -> 4.6772363e+10 | D92: ='1.Reel GSYH '!D88 -> 464333.1 | E92: ='1.Reel GSYH '!K88 -> 58229366140 | F92: ='1.Reel GSYH '!N88 -> 0 | G92: ='1.Reel GSYH '!Q88 -> 0 | H92: ='1.Reel GSYH '!U88 -> 0 | I92: ='1.Reel GSYH '!Y88 -> -11457467500 | K92: =(D96/D92-1)*100 -> 11.08717 | P92: =(I96/I92-1)*100 -> 106.22048 | R92: =(B96/B92-1)*100 -> -9.9484975 | T92: =((D96-D92)/($B92))*100 -> 0.00011006799 | U92: =((E92-E88)/($B88))*100 -> 26.023096 | V92: =((F92-F88)/($B88))*100 -> 0 | W92: =((G92-G88)/($B88))*100 -> 0 | X92: =((H92-H88)/($B88))*100 -> 0 | Y92: =((I96-I92)/($B92))*100 -> -26.020017
... A107: Q3-2016 | B107: ='1.Reel GSYH '!B103 -> 7.8800443e+10 | D107: ='1.Reel GSYH '!D103 -> 633640.3 | E107: ='1.Reel GSYH '!K103 -> 93948421030 | F107: ='1.Reel GSYH '!N103 -> 0 | G107: ='1.Reel GSYH '!Q103 -> 0 | H107: ='1.Reel GSYH '!U103 -> 0 | I107: ='1.Reel GSYH '!Y103 -> -15148611500 | K107: =(D111/D107-1)*100 -> -100 | P107: =(I111/I107-1)*100 -> -95.903332 | R107: =(B111/B107-1)*100 -> -100 | T107: =((D111-D107)/($B107))*100 -> -0.00080410753 | U107: =((E107-E103)/($B103))*100 -> 13.872063 | V107: =((F107-F103)/($B103))*100 -> 0 | W107: =((G107-G103)/($B103))*100 -> 0 | X107: =((H107-H103)/($B103))*100 -> 0 | Y107: =((I111-I107)/($B107))*100 -> 18.436474
...

Sheet 1d. Katkı Grafikleri
B1: Ülke Analizi
B2: Toplam Talep Analizi
B3: GSYH Büyümesine Katkı

Sheet 2.Özel Tüketim
B1: Ülke Analizi
B2: Toplam Talep Analizi
B3: Özel Tüketim Analizi
K9: =(D12/$B12)*100 | L9: =E12/$B12*100 | M9: =F12/$B12*100 | N9: =G12/$B12*100 | O9: =H12/$B12*100 | P9: =I12/$B12*100 | V9: =(H16/H12-1)*100 | Y9: =(B16/B12-1)*100 | Z9: =((D16-D12)/$B12)*100 | AA9: =((E16-E12)/$B12)*100
D10: Reel Özel Tüketim Bileşenleri (Düzey, 2008 Fiyatları-DND Milyar) | K10: Real Özel Tüketim (GSYH içindeki payı %) | R10: Özel Tüketim Büyüme Oranları (% YoY) | Y10: Özel Tüketim Bileşenlerinin Büyümeye Katkısı (% YoY)
